ERROR 2024-12-06 02:52:22,395 quote_service 31008 31516 Unexpected error in quote generation
Traceback (most recent call last):
  File "C:\Projects\Mustafa\NOTFINAL\SOLARSIZING\Solar_Sizing_Bill_Calculator_With_AI_Backend\solar\services\quote_service.py", line 68, in generate_quote
    yearly_units = float(bill_data['Total Yearly Units'])
                         ~~~~~~~~~^^^^^^^^^^^^^^^^^^^^^^
KeyError: 'Total Yearly Units'
ERROR 2024-12-06 02:52:22,395 quote_views 31008 31516 Error in quote generation service
Traceback (most recent call last):
  File "C:\Projects\Mustafa\NOTFINAL\SOLARSIZING\Solar_Sizing_Bill_Calculator_With_AI_Backend\solar\services\quote_service.py", line 68, in generate_quote
    yearly_units = float(bill_data['Total Yearly Units'])
                         ~~~~~~~~~^^^^^^^^^^^^^^^^^^^^^^
KeyError: 'Total Yearly Units'

During handling of the above exception, another exception occurred:

Traceback (most recent call last):
  File "C:\Projects\Mustafa\NOTFINAL\SOLARSIZING\Solar_Sizing_Bill_Calculator_With_AI_Backend\solar\views\quote_views.py", line 38, in post
    quote_data = QuoteService.generate_quote(request.data)
                 ^^^^^^^^^^^^^^^^^^^^^^^^^^^^^^^^^^^^^^^^^
  File "C:\Projects\Mustafa\NOTFINAL\SOLARSIZING\Solar_Sizing_Bill_Calculator_With_AI_Backend\solar\services\quote_service.py", line 117, in generate_quote
    raise AppError(
solar.middleware.error_handler.AppError: Failed to generate quote
ERROR 2024-12-06 02:57:33,293 quote_service 15104 31328 Missing required field: 'Total Yearly Units'
ERROR 2024-12-06 02:57:33,293 quote_views 15104 31328 Error in quote generation
Traceback (most recent call last):
  File "C:\Projects\Mustafa\NOTFINAL\SOLARSIZING\Solar_Sizing_Bill_Calculator_With_AI_Backend\solar\services\quote_service.py", line 68, in generate_quote
    yearly_units = float(bill_data['Total Yearly Units'])
                         ~~~~~~~~~^^^^^^^^^^^^^^^^^^^^^^
KeyError: 'Total Yearly Units'

During handling of the above exception, another exception occurred:

Traceback (most recent call last):
  File "C:\Projects\Mustafa\NOTFINAL\SOLARSIZING\Solar_Sizing_Bill_Calculator_With_AI_Backend\solar\views\quote_views.py", line 46, in post
    quote_data = QuoteService.generate_quote(request.data)
                 ^^^^^^^^^^^^^^^^^^^^^^^^^^^^^^^^^^^^^^^^^
  File "C:\Projects\Mustafa\NOTFINAL\SOLARSIZING\Solar_Sizing_Bill_Calculator_With_AI_Backend\solar\services\quote_service.py", line 115, in generate_quote
    raise AppError(
solar.middleware.error_handler.AppError: Missing required field: 'Total Yearly Units'
ERROR 2024-12-06 03:01:36,228 quote_service 19360 24416 Unexpected error in quote generation
Traceback (most recent call last):
  File "C:\Projects\Mustafa\NOTFINAL\SOLARSIZING\Solar_Sizing_Bill_Calculator_With_AI_Backend\solar\services\quote_service.py", line 198, in _get_all_costs
    'dc_cable': bracket_costs['dc_cable'],
                ~~~~~~~~~~~~~^^^^^^^^^^^^
KeyError: 'dc_cable'

During handling of the above exception, another exception occurred:

Traceback (most recent call last):
  File "C:\Projects\Mustafa\NOTFINAL\SOLARSIZING\Solar_Sizing_Bill_Calculator_With_AI_Backend\solar\services\quote_service.py", line 83, in generate_quote
    costs = cls._get_all_costs(system_size, panels_needed)
            ^^^^^^^^^^^^^^^^^^^^^^^^^^^^^^^^^^^^^^^^^^^^^^
  File "C:\Projects\Mustafa\NOTFINAL\SOLARSIZING\Solar_Sizing_Bill_Calculator_With_AI_Backend\solar\services\quote_service.py", line 207, in _get_all_costs
    raise AppError(
solar.middleware.error_handler.AppError: Failed to retrieve costs
ERROR 2024-12-06 03:01:36,231 quote_views 19360 24416 Error in quote generation
Traceback (most recent call last):
  File "C:\Projects\Mustafa\NOTFINAL\SOLARSIZING\Solar_Sizing_Bill_Calculator_With_AI_Backend\solar\services\quote_service.py", line 198, in _get_all_costs
    'dc_cable': bracket_costs['dc_cable'],
                ~~~~~~~~~~~~~^^^^^^^^^^^^
KeyError: 'dc_cable'

During handling of the above exception, another exception occurred:

Traceback (most recent call last):
  File "C:\Projects\Mustafa\NOTFINAL\SOLARSIZING\Solar_Sizing_Bill_Calculator_With_AI_Backend\solar\services\quote_service.py", line 83, in generate_quote
    costs = cls._get_all_costs(system_size, panels_needed)
            ^^^^^^^^^^^^^^^^^^^^^^^^^^^^^^^^^^^^^^^^^^^^^^
  File "C:\Projects\Mustafa\NOTFINAL\SOLARSIZING\Solar_Sizing_Bill_Calculator_With_AI_Backend\solar\services\quote_service.py", line 207, in _get_all_costs
    raise AppError(
solar.middleware.error_handler.AppError: Failed to retrieve costs

During handling of the above exception, another exception occurred:

Traceback (most recent call last):
  File "C:\Projects\Mustafa\NOTFINAL\SOLARSIZING\Solar_Sizing_Bill_Calculator_With_AI_Backend\solar\views\quote_views.py", line 46, in post
    quote_data = QuoteService.generate_quote(request.data)
                 ^^^^^^^^^^^^^^^^^^^^^^^^^^^^^^^^^^^^^^^^^
  File "C:\Projects\Mustafa\NOTFINAL\SOLARSIZING\Solar_Sizing_Bill_Calculator_With_AI_Backend\solar\services\quote_service.py", line 134, in generate_quote
    raise AppError(
solar.middleware.error_handler.AppError: Failed to generate quote
ERROR 2024-12-06 03:06:03,107 quote_service 34740 20204 Cost calculation failed: Failed to retrieve costs
ERROR 2024-12-06 03:06:03,107 quote_service 34740 20204 Quote generation failed with AppError: Failed to retrieve costs
ERROR 2024-12-06 03:06:03,107 quote_views 34740 20204 Error in quote generation
Traceback (most recent call last):
  File "C:\Projects\Mustafa\NOTFINAL\SOLARSIZING\Solar_Sizing_Bill_Calculator_With_AI_Backend\solar\services\quote_service.py", line 215, in _get_all_costs
    'dc_cable': bracket_costs['dc_cable'],
                ~~~~~~~~~~~~~^^^^^^^^^^^^
KeyError: 'dc_cable'

During handling of the above exception, another exception occurred:

Traceback (most recent call last):
  File "C:\Projects\Mustafa\NOTFINAL\SOLARSIZING\Solar_Sizing_Bill_Calculator_With_AI_Backend\solar\views\quote_views.py", line 46, in post
    quote_data = QuoteService.generate_quote(request.data)
                 ^^^^^^^^^^^^^^^^^^^^^^^^^^^^^^^^^^^^^^^^^
  File "C:\Projects\Mustafa\NOTFINAL\SOLARSIZING\Solar_Sizing_Bill_Calculator_With_AI_Backend\solar\services\quote_service.py", line 91, in generate_quote
    costs = cls._get_all_costs(system_size, panels_needed)
            ^^^^^^^^^^^^^^^^^^^^^^^^^^^^^^^^^^^^^^^^^^^^^^
  File "C:\Projects\Mustafa\NOTFINAL\SOLARSIZING\Solar_Sizing_Bill_Calculator_With_AI_Backend\solar\services\quote_service.py", line 224, in _get_all_costs
    raise AppError(
solar.middleware.error_handler.AppError: Failed to retrieve costs
ERROR 2024-12-06 03:10:52,058 inventory_service 28504 23060 Error retrieving bracket costs
Traceback (most recent call last):
  File "C:\Projects\Mustafa\NOTFINAL\SOLARSIZING\Solar_Sizing_Bill_Calculator_With_AI_Backend\solar\services\inventory_service.py", line 234, in get_bracket_costs
    bracket = BracketCosts.objects.filter(
              ^^^^^^^^^^^^^^^^^^^^^^^^^^^^
  File "C:\Projects\Mustafa\NOTFINAL\SOLARSIZING\Solar_Sizing_Bill_Calculator_With_AI_Backend\venv\Lib\site-packages\django\db\models\manager.py", line 87, in manager_method
    return getattr(self.get_queryset(), name)(*args, **kwargs)
           ^^^^^^^^^^^^^^^^^^^^^^^^^^^^^^^^^^^^^^^^^^^^^^^^^^^
  File "C:\Projects\Mustafa\NOTFINAL\SOLARSIZING\Solar_Sizing_Bill_Calculator_With_AI_Backend\venv\Lib\site-packages\django\db\models\query.py", line 1476, in filter
    return self._filter_or_exclude(False, args, kwargs)
           ^^^^^^^^^^^^^^^^^^^^^^^^^^^^^^^^^^^^^^^^^^^^
  File "C:\Projects\Mustafa\NOTFINAL\SOLARSIZING\Solar_Sizing_Bill_Calculator_With_AI_Backend\venv\Lib\site-packages\django\db\models\query.py", line 1494, in _filter_or_exclude
    clone._filter_or_exclude_inplace(negate, args, kwargs)
  File "C:\Projects\Mustafa\NOTFINAL\SOLARSIZING\Solar_Sizing_Bill_Calculator_With_AI_Backend\venv\Lib\site-packages\django\db\models\query.py", line 1501, in _filter_or_exclude_inplace
    self._query.add_q(Q(*args, **kwargs))
  File "C:\Projects\Mustafa\NOTFINAL\SOLARSIZING\Solar_Sizing_Bill_Calculator_With_AI_Backend\venv\Lib\site-packages\django\db\models\sql\query.py", line 1609, in add_q
    clause, _ = self._add_q(q_object, self.used_aliases)
                ^^^^^^^^^^^^^^^^^^^^^^^^^^^^^^^^^^^^^^^^
  File "C:\Projects\Mustafa\NOTFINAL\SOLARSIZING\Solar_Sizing_Bill_Calculator_With_AI_Backend\venv\Lib\site-packages\django\db\models\sql\query.py", line 1641, in _add_q
    child_clause, needed_inner = self.build_filter(
                                 ^^^^^^^^^^^^^^^^^^
  File "C:\Projects\Mustafa\NOTFINAL\SOLARSIZING\Solar_Sizing_Bill_Calculator_With_AI_Backend\venv\Lib\site-packages\django\db\models\sql\query.py", line 1491, in build_filter
    lookups, parts, reffed_expression = self.solve_lookup_type(arg, summarize)
                                        ^^^^^^^^^^^^^^^^^^^^^^^^^^^^^^^^^^^^^^
  File "C:\Projects\Mustafa\NOTFINAL\SOLARSIZING\Solar_Sizing_Bill_Calculator_With_AI_Backend\venv\Lib\site-packages\django\db\models\sql\query.py", line 1303, in solve_lookup_type
    _, field, _, lookup_parts = self.names_to_path(lookup_splitted, self.get_meta())
                                ^^^^^^^^^^^^^^^^^^^^^^^^^^^^^^^^^^^^^^^^^^^^^^^^^^^^
  File "C:\Projects\Mustafa\NOTFINAL\SOLARSIZING\Solar_Sizing_Bill_Calculator_With_AI_Backend\venv\Lib\site-packages\django\db\models\sql\query.py", line 1768, in names_to_path
    raise FieldError(
django.core.exceptions.FieldError: Cannot resolve keyword 'max_size' into field. Choices are: SystemRange, Type, cost, id
ERROR 2024-12-06 03:10:52,061 quote_service 28504 23060 Error calculating costs
Traceback (most recent call last):
  File "C:\Projects\Mustafa\NOTFINAL\SOLARSIZING\Solar_Sizing_Bill_Calculator_With_AI_Backend\solar\services\inventory_service.py", line 234, in get_bracket_costs
    bracket = BracketCosts.objects.filter(
              ^^^^^^^^^^^^^^^^^^^^^^^^^^^^
  File "C:\Projects\Mustafa\NOTFINAL\SOLARSIZING\Solar_Sizing_Bill_Calculator_With_AI_Backend\venv\Lib\site-packages\django\db\models\manager.py", line 87, in manager_method
    return getattr(self.get_queryset(), name)(*args, **kwargs)
           ^^^^^^^^^^^^^^^^^^^^^^^^^^^^^^^^^^^^^^^^^^^^^^^^^^^
  File "C:\Projects\Mustafa\NOTFINAL\SOLARSIZING\Solar_Sizing_Bill_Calculator_With_AI_Backend\venv\Lib\site-packages\django\db\models\query.py", line 1476, in filter
    return self._filter_or_exclude(False, args, kwargs)
           ^^^^^^^^^^^^^^^^^^^^^^^^^^^^^^^^^^^^^^^^^^^^
  File "C:\Projects\Mustafa\NOTFINAL\SOLARSIZING\Solar_Sizing_Bill_Calculator_With_AI_Backend\venv\Lib\site-packages\django\db\models\query.py", line 1494, in _filter_or_exclude
    clone._filter_or_exclude_inplace(negate, args, kwargs)
  File "C:\Projects\Mustafa\NOTFINAL\SOLARSIZING\Solar_Sizing_Bill_Calculator_With_AI_Backend\venv\Lib\site-packages\django\db\models\query.py", line 1501, in _filter_or_exclude_inplace
    self._query.add_q(Q(*args, **kwargs))
  File "C:\Projects\Mustafa\NOTFINAL\SOLARSIZING\Solar_Sizing_Bill_Calculator_With_AI_Backend\venv\Lib\site-packages\django\db\models\sql\query.py", line 1609, in add_q
    clause, _ = self._add_q(q_object, self.used_aliases)
                ^^^^^^^^^^^^^^^^^^^^^^^^^^^^^^^^^^^^^^^^
  File "C:\Projects\Mustafa\NOTFINAL\SOLARSIZING\Solar_Sizing_Bill_Calculator_With_AI_Backend\venv\Lib\site-packages\django\db\models\sql\query.py", line 1641, in _add_q
    child_clause, needed_inner = self.build_filter(
                                 ^^^^^^^^^^^^^^^^^^
  File "C:\Projects\Mustafa\NOTFINAL\SOLARSIZING\Solar_Sizing_Bill_Calculator_With_AI_Backend\venv\Lib\site-packages\django\db\models\sql\query.py", line 1491, in build_filter
    lookups, parts, reffed_expression = self.solve_lookup_type(arg, summarize)
                                        ^^^^^^^^^^^^^^^^^^^^^^^^^^^^^^^^^^^^^^
  File "C:\Projects\Mustafa\NOTFINAL\SOLARSIZING\Solar_Sizing_Bill_Calculator_With_AI_Backend\venv\Lib\site-packages\django\db\models\sql\query.py", line 1303, in solve_lookup_type
    _, field, _, lookup_parts = self.names_to_path(lookup_splitted, self.get_meta())
                                ^^^^^^^^^^^^^^^^^^^^^^^^^^^^^^^^^^^^^^^^^^^^^^^^^^^^
  File "C:\Projects\Mustafa\NOTFINAL\SOLARSIZING\Solar_Sizing_Bill_Calculator_With_AI_Backend\venv\Lib\site-packages\django\db\models\sql\query.py", line 1768, in names_to_path
    raise FieldError(
django.core.exceptions.FieldError: Cannot resolve keyword 'max_size' into field. Choices are: SystemRange, Type, cost, id

During handling of the above exception, another exception occurred:

Traceback (most recent call last):
  File "C:\Projects\Mustafa\NOTFINAL\SOLARSIZING\Solar_Sizing_Bill_Calculator_With_AI_Backend\solar\services\quote_service.py", line 228, in _get_all_costs
    bracket_costs = InventoryService.get_bracket_costs(system_size)
                    ^^^^^^^^^^^^^^^^^^^^^^^^^^^^^^^^^^^^^^^^^^^^^^^
  File "C:\Projects\Mustafa\NOTFINAL\SOLARSIZING\Solar_Sizing_Bill_Calculator_With_AI_Backend\solar\services\inventory_service.py", line 261, in get_bracket_costs
    raise AppError(
solar.middleware.error_handler.AppError: Failed to retrieve bracket costs
ERROR 2024-12-06 03:10:52,061 quote_service 28504 23060 Cost calculation failed: Failed to retrieve costs
ERROR 2024-12-06 03:10:52,061 quote_service 28504 23060 Quote generation failed with AppError: Failed to retrieve costs
ERROR 2024-12-06 03:10:52,061 quote_views 28504 23060 Error in quote generation
Traceback (most recent call last):
  File "C:\Projects\Mustafa\NOTFINAL\SOLARSIZING\Solar_Sizing_Bill_Calculator_With_AI_Backend\solar\services\inventory_service.py", line 234, in get_bracket_costs
    bracket = BracketCosts.objects.filter(
              ^^^^^^^^^^^^^^^^^^^^^^^^^^^^
  File "C:\Projects\Mustafa\NOTFINAL\SOLARSIZING\Solar_Sizing_Bill_Calculator_With_AI_Backend\venv\Lib\site-packages\django\db\models\manager.py", line 87, in manager_method
    return getattr(self.get_queryset(), name)(*args, **kwargs)
           ^^^^^^^^^^^^^^^^^^^^^^^^^^^^^^^^^^^^^^^^^^^^^^^^^^^
  File "C:\Projects\Mustafa\NOTFINAL\SOLARSIZING\Solar_Sizing_Bill_Calculator_With_AI_Backend\venv\Lib\site-packages\django\db\models\query.py", line 1476, in filter
    return self._filter_or_exclude(False, args, kwargs)
           ^^^^^^^^^^^^^^^^^^^^^^^^^^^^^^^^^^^^^^^^^^^^
  File "C:\Projects\Mustafa\NOTFINAL\SOLARSIZING\Solar_Sizing_Bill_Calculator_With_AI_Backend\venv\Lib\site-packages\django\db\models\query.py", line 1494, in _filter_or_exclude
    clone._filter_or_exclude_inplace(negate, args, kwargs)
  File "C:\Projects\Mustafa\NOTFINAL\SOLARSIZING\Solar_Sizing_Bill_Calculator_With_AI_Backend\venv\Lib\site-packages\django\db\models\query.py", line 1501, in _filter_or_exclude_inplace
    self._query.add_q(Q(*args, **kwargs))
  File "C:\Projects\Mustafa\NOTFINAL\SOLARSIZING\Solar_Sizing_Bill_Calculator_With_AI_Backend\venv\Lib\site-packages\django\db\models\sql\query.py", line 1609, in add_q
    clause, _ = self._add_q(q_object, self.used_aliases)
                ^^^^^^^^^^^^^^^^^^^^^^^^^^^^^^^^^^^^^^^^
  File "C:\Projects\Mustafa\NOTFINAL\SOLARSIZING\Solar_Sizing_Bill_Calculator_With_AI_Backend\venv\Lib\site-packages\django\db\models\sql\query.py", line 1641, in _add_q
    child_clause, needed_inner = self.build_filter(
                                 ^^^^^^^^^^^^^^^^^^
  File "C:\Projects\Mustafa\NOTFINAL\SOLARSIZING\Solar_Sizing_Bill_Calculator_With_AI_Backend\venv\Lib\site-packages\django\db\models\sql\query.py", line 1491, in build_filter
    lookups, parts, reffed_expression = self.solve_lookup_type(arg, summarize)
                                        ^^^^^^^^^^^^^^^^^^^^^^^^^^^^^^^^^^^^^^
  File "C:\Projects\Mustafa\NOTFINAL\SOLARSIZING\Solar_Sizing_Bill_Calculator_With_AI_Backend\venv\Lib\site-packages\django\db\models\sql\query.py", line 1303, in solve_lookup_type
    _, field, _, lookup_parts = self.names_to_path(lookup_splitted, self.get_meta())
                                ^^^^^^^^^^^^^^^^^^^^^^^^^^^^^^^^^^^^^^^^^^^^^^^^^^^^
  File "C:\Projects\Mustafa\NOTFINAL\SOLARSIZING\Solar_Sizing_Bill_Calculator_With_AI_Backend\venv\Lib\site-packages\django\db\models\sql\query.py", line 1768, in names_to_path
    raise FieldError(
django.core.exceptions.FieldError: Cannot resolve keyword 'max_size' into field. Choices are: SystemRange, Type, cost, id

During handling of the above exception, another exception occurred:

Traceback (most recent call last):
  File "C:\Projects\Mustafa\NOTFINAL\SOLARSIZING\Solar_Sizing_Bill_Calculator_With_AI_Backend\solar\services\quote_service.py", line 228, in _get_all_costs
    bracket_costs = InventoryService.get_bracket_costs(system_size)
                    ^^^^^^^^^^^^^^^^^^^^^^^^^^^^^^^^^^^^^^^^^^^^^^^
  File "C:\Projects\Mustafa\NOTFINAL\SOLARSIZING\Solar_Sizing_Bill_Calculator_With_AI_Backend\solar\services\inventory_service.py", line 261, in get_bracket_costs
    raise AppError(
solar.middleware.error_handler.AppError: Failed to retrieve bracket costs

During handling of the above exception, another exception occurred:

Traceback (most recent call last):
  File "C:\Projects\Mustafa\NOTFINAL\SOLARSIZING\Solar_Sizing_Bill_Calculator_With_AI_Backend\solar\views\quote_views.py", line 46, in post
    quote_data = QuoteService.generate_quote(request.data)
                 ^^^^^^^^^^^^^^^^^^^^^^^^^^^^^^^^^^^^^^^^^
  File "C:\Projects\Mustafa\NOTFINAL\SOLARSIZING\Solar_Sizing_Bill_Calculator_With_AI_Backend\solar\services\quote_service.py", line 91, in generate_quote
    costs = cls._get_all_costs(system_size, panels_needed)
            ^^^^^^^^^^^^^^^^^^^^^^^^^^^^^^^^^^^^^^^^^^^^^^
  File "C:\Projects\Mustafa\NOTFINAL\SOLARSIZING\Solar_Sizing_Bill_Calculator_With_AI_Backend\solar\services\quote_service.py", line 249, in _get_all_costs
    raise AppError(
solar.middleware.error_handler.AppError: Failed to retrieve costs
ERROR 2024-12-06 03:11:22,212 inventory_service 28504 31856 Error retrieving bracket costs
Traceback (most recent call last):
  File "C:\Projects\Mustafa\NOTFINAL\SOLARSIZING\Solar_Sizing_Bill_Calculator_With_AI_Backend\solar\services\inventory_service.py", line 234, in get_bracket_costs
    bracket = BracketCosts.objects.filter(
              ^^^^^^^^^^^^^^^^^^^^^^^^^^^^
  File "C:\Projects\Mustafa\NOTFINAL\SOLARSIZING\Solar_Sizing_Bill_Calculator_With_AI_Backend\venv\Lib\site-packages\django\db\models\manager.py", line 87, in manager_method
    return getattr(self.get_queryset(), name)(*args, **kwargs)
           ^^^^^^^^^^^^^^^^^^^^^^^^^^^^^^^^^^^^^^^^^^^^^^^^^^^
  File "C:\Projects\Mustafa\NOTFINAL\SOLARSIZING\Solar_Sizing_Bill_Calculator_With_AI_Backend\venv\Lib\site-packages\django\db\models\query.py", line 1476, in filter
    return self._filter_or_exclude(False, args, kwargs)
           ^^^^^^^^^^^^^^^^^^^^^^^^^^^^^^^^^^^^^^^^^^^^
  File "C:\Projects\Mustafa\NOTFINAL\SOLARSIZING\Solar_Sizing_Bill_Calculator_With_AI_Backend\venv\Lib\site-packages\django\db\models\query.py", line 1494, in _filter_or_exclude
    clone._filter_or_exclude_inplace(negate, args, kwargs)
  File "C:\Projects\Mustafa\NOTFINAL\SOLARSIZING\Solar_Sizing_Bill_Calculator_With_AI_Backend\venv\Lib\site-packages\django\db\models\query.py", line 1501, in _filter_or_exclude_inplace
    self._query.add_q(Q(*args, **kwargs))
  File "C:\Projects\Mustafa\NOTFINAL\SOLARSIZING\Solar_Sizing_Bill_Calculator_With_AI_Backend\venv\Lib\site-packages\django\db\models\sql\query.py", line 1609, in add_q
    clause, _ = self._add_q(q_object, self.used_aliases)
                ^^^^^^^^^^^^^^^^^^^^^^^^^^^^^^^^^^^^^^^^
  File "C:\Projects\Mustafa\NOTFINAL\SOLARSIZING\Solar_Sizing_Bill_Calculator_With_AI_Backend\venv\Lib\site-packages\django\db\models\sql\query.py", line 1641, in _add_q
    child_clause, needed_inner = self.build_filter(
                                 ^^^^^^^^^^^^^^^^^^
  File "C:\Projects\Mustafa\NOTFINAL\SOLARSIZING\Solar_Sizing_Bill_Calculator_With_AI_Backend\venv\Lib\site-packages\django\db\models\sql\query.py", line 1491, in build_filter
    lookups, parts, reffed_expression = self.solve_lookup_type(arg, summarize)
                                        ^^^^^^^^^^^^^^^^^^^^^^^^^^^^^^^^^^^^^^
  File "C:\Projects\Mustafa\NOTFINAL\SOLARSIZING\Solar_Sizing_Bill_Calculator_With_AI_Backend\venv\Lib\site-packages\django\db\models\sql\query.py", line 1303, in solve_lookup_type
    _, field, _, lookup_parts = self.names_to_path(lookup_splitted, self.get_meta())
                                ^^^^^^^^^^^^^^^^^^^^^^^^^^^^^^^^^^^^^^^^^^^^^^^^^^^^
  File "C:\Projects\Mustafa\NOTFINAL\SOLARSIZING\Solar_Sizing_Bill_Calculator_With_AI_Backend\venv\Lib\site-packages\django\db\models\sql\query.py", line 1768, in names_to_path
    raise FieldError(
django.core.exceptions.FieldError: Cannot resolve keyword 'max_size' into field. Choices are: SystemRange, Type, cost, id
ERROR 2024-12-06 03:11:22,213 quote_service 28504 31856 Error calculating costs
Traceback (most recent call last):
  File "C:\Projects\Mustafa\NOTFINAL\SOLARSIZING\Solar_Sizing_Bill_Calculator_With_AI_Backend\solar\services\inventory_service.py", line 234, in get_bracket_costs
    bracket = BracketCosts.objects.filter(
              ^^^^^^^^^^^^^^^^^^^^^^^^^^^^
  File "C:\Projects\Mustafa\NOTFINAL\SOLARSIZING\Solar_Sizing_Bill_Calculator_With_AI_Backend\venv\Lib\site-packages\django\db\models\manager.py", line 87, in manager_method
    return getattr(self.get_queryset(), name)(*args, **kwargs)
           ^^^^^^^^^^^^^^^^^^^^^^^^^^^^^^^^^^^^^^^^^^^^^^^^^^^
  File "C:\Projects\Mustafa\NOTFINAL\SOLARSIZING\Solar_Sizing_Bill_Calculator_With_AI_Backend\venv\Lib\site-packages\django\db\models\query.py", line 1476, in filter
    return self._filter_or_exclude(False, args, kwargs)
           ^^^^^^^^^^^^^^^^^^^^^^^^^^^^^^^^^^^^^^^^^^^^
  File "C:\Projects\Mustafa\NOTFINAL\SOLARSIZING\Solar_Sizing_Bill_Calculator_With_AI_Backend\venv\Lib\site-packages\django\db\models\query.py", line 1494, in _filter_or_exclude
    clone._filter_or_exclude_inplace(negate, args, kwargs)
  File "C:\Projects\Mustafa\NOTFINAL\SOLARSIZING\Solar_Sizing_Bill_Calculator_With_AI_Backend\venv\Lib\site-packages\django\db\models\query.py", line 1501, in _filter_or_exclude_inplace
    self._query.add_q(Q(*args, **kwargs))
  File "C:\Projects\Mustafa\NOTFINAL\SOLARSIZING\Solar_Sizing_Bill_Calculator_With_AI_Backend\venv\Lib\site-packages\django\db\models\sql\query.py", line 1609, in add_q
    clause, _ = self._add_q(q_object, self.used_aliases)
                ^^^^^^^^^^^^^^^^^^^^^^^^^^^^^^^^^^^^^^^^
  File "C:\Projects\Mustafa\NOTFINAL\SOLARSIZING\Solar_Sizing_Bill_Calculator_With_AI_Backend\venv\Lib\site-packages\django\db\models\sql\query.py", line 1641, in _add_q
    child_clause, needed_inner = self.build_filter(
                                 ^^^^^^^^^^^^^^^^^^
  File "C:\Projects\Mustafa\NOTFINAL\SOLARSIZING\Solar_Sizing_Bill_Calculator_With_AI_Backend\venv\Lib\site-packages\django\db\models\sql\query.py", line 1491, in build_filter
    lookups, parts, reffed_expression = self.solve_lookup_type(arg, summarize)
                                        ^^^^^^^^^^^^^^^^^^^^^^^^^^^^^^^^^^^^^^
  File "C:\Projects\Mustafa\NOTFINAL\SOLARSIZING\Solar_Sizing_Bill_Calculator_With_AI_Backend\venv\Lib\site-packages\django\db\models\sql\query.py", line 1303, in solve_lookup_type
    _, field, _, lookup_parts = self.names_to_path(lookup_splitted, self.get_meta())
                                ^^^^^^^^^^^^^^^^^^^^^^^^^^^^^^^^^^^^^^^^^^^^^^^^^^^^
  File "C:\Projects\Mustafa\NOTFINAL\SOLARSIZING\Solar_Sizing_Bill_Calculator_With_AI_Backend\venv\Lib\site-packages\django\db\models\sql\query.py", line 1768, in names_to_path
    raise FieldError(
django.core.exceptions.FieldError: Cannot resolve keyword 'max_size' into field. Choices are: SystemRange, Type, cost, id

During handling of the above exception, another exception occurred:

Traceback (most recent call last):
  File "C:\Projects\Mustafa\NOTFINAL\SOLARSIZING\Solar_Sizing_Bill_Calculator_With_AI_Backend\solar\services\quote_service.py", line 228, in _get_all_costs
    bracket_costs = InventoryService.get_bracket_costs(system_size)
                    ^^^^^^^^^^^^^^^^^^^^^^^^^^^^^^^^^^^^^^^^^^^^^^^
  File "C:\Projects\Mustafa\NOTFINAL\SOLARSIZING\Solar_Sizing_Bill_Calculator_With_AI_Backend\solar\services\inventory_service.py", line 261, in get_bracket_costs
    raise AppError(
solar.middleware.error_handler.AppError: Failed to retrieve bracket costs
ERROR 2024-12-06 03:11:22,214 quote_service 28504 31856 Cost calculation failed: Failed to retrieve costs
ERROR 2024-12-06 03:11:22,214 quote_service 28504 31856 Quote generation failed with AppError: Failed to retrieve costs
ERROR 2024-12-06 03:11:22,215 quote_views 28504 31856 Error in quote generation
Traceback (most recent call last):
  File "C:\Projects\Mustafa\NOTFINAL\SOLARSIZING\Solar_Sizing_Bill_Calculator_With_AI_Backend\solar\services\inventory_service.py", line 234, in get_bracket_costs
    bracket = BracketCosts.objects.filter(
              ^^^^^^^^^^^^^^^^^^^^^^^^^^^^
  File "C:\Projects\Mustafa\NOTFINAL\SOLARSIZING\Solar_Sizing_Bill_Calculator_With_AI_Backend\venv\Lib\site-packages\django\db\models\manager.py", line 87, in manager_method
    return getattr(self.get_queryset(), name)(*args, **kwargs)
           ^^^^^^^^^^^^^^^^^^^^^^^^^^^^^^^^^^^^^^^^^^^^^^^^^^^
  File "C:\Projects\Mustafa\NOTFINAL\SOLARSIZING\Solar_Sizing_Bill_Calculator_With_AI_Backend\venv\Lib\site-packages\django\db\models\query.py", line 1476, in filter
    return self._filter_or_exclude(False, args, kwargs)
           ^^^^^^^^^^^^^^^^^^^^^^^^^^^^^^^^^^^^^^^^^^^^
  File "C:\Projects\Mustafa\NOTFINAL\SOLARSIZING\Solar_Sizing_Bill_Calculator_With_AI_Backend\venv\Lib\site-packages\django\db\models\query.py", line 1494, in _filter_or_exclude
    clone._filter_or_exclude_inplace(negate, args, kwargs)
  File "C:\Projects\Mustafa\NOTFINAL\SOLARSIZING\Solar_Sizing_Bill_Calculator_With_AI_Backend\venv\Lib\site-packages\django\db\models\query.py", line 1501, in _filter_or_exclude_inplace
    self._query.add_q(Q(*args, **kwargs))
  File "C:\Projects\Mustafa\NOTFINAL\SOLARSIZING\Solar_Sizing_Bill_Calculator_With_AI_Backend\venv\Lib\site-packages\django\db\models\sql\query.py", line 1609, in add_q
    clause, _ = self._add_q(q_object, self.used_aliases)
                ^^^^^^^^^^^^^^^^^^^^^^^^^^^^^^^^^^^^^^^^
  File "C:\Projects\Mustafa\NOTFINAL\SOLARSIZING\Solar_Sizing_Bill_Calculator_With_AI_Backend\venv\Lib\site-packages\django\db\models\sql\query.py", line 1641, in _add_q
    child_clause, needed_inner = self.build_filter(
                                 ^^^^^^^^^^^^^^^^^^
  File "C:\Projects\Mustafa\NOTFINAL\SOLARSIZING\Solar_Sizing_Bill_Calculator_With_AI_Backend\venv\Lib\site-packages\django\db\models\sql\query.py", line 1491, in build_filter
    lookups, parts, reffed_expression = self.solve_lookup_type(arg, summarize)
                                        ^^^^^^^^^^^^^^^^^^^^^^^^^^^^^^^^^^^^^^
  File "C:\Projects\Mustafa\NOTFINAL\SOLARSIZING\Solar_Sizing_Bill_Calculator_With_AI_Backend\venv\Lib\site-packages\django\db\models\sql\query.py", line 1303, in solve_lookup_type
    _, field, _, lookup_parts = self.names_to_path(lookup_splitted, self.get_meta())
                                ^^^^^^^^^^^^^^^^^^^^^^^^^^^^^^^^^^^^^^^^^^^^^^^^^^^^
  File "C:\Projects\Mustafa\NOTFINAL\SOLARSIZING\Solar_Sizing_Bill_Calculator_With_AI_Backend\venv\Lib\site-packages\django\db\models\sql\query.py", line 1768, in names_to_path
    raise FieldError(
django.core.exceptions.FieldError: Cannot resolve keyword 'max_size' into field. Choices are: SystemRange, Type, cost, id

During handling of the above exception, another exception occurred:

Traceback (most recent call last):
  File "C:\Projects\Mustafa\NOTFINAL\SOLARSIZING\Solar_Sizing_Bill_Calculator_With_AI_Backend\solar\services\quote_service.py", line 228, in _get_all_costs
    bracket_costs = InventoryService.get_bracket_costs(system_size)
                    ^^^^^^^^^^^^^^^^^^^^^^^^^^^^^^^^^^^^^^^^^^^^^^^
  File "C:\Projects\Mustafa\NOTFINAL\SOLARSIZING\Solar_Sizing_Bill_Calculator_With_AI_Backend\solar\services\inventory_service.py", line 261, in get_bracket_costs
    raise AppError(
solar.middleware.error_handler.AppError: Failed to retrieve bracket costs

During handling of the above exception, another exception occurred:

Traceback (most recent call last):
  File "C:\Projects\Mustafa\NOTFINAL\SOLARSIZING\Solar_Sizing_Bill_Calculator_With_AI_Backend\solar\views\quote_views.py", line 46, in post
    quote_data = QuoteService.generate_quote(request.data)
                 ^^^^^^^^^^^^^^^^^^^^^^^^^^^^^^^^^^^^^^^^^
  File "C:\Projects\Mustafa\NOTFINAL\SOLARSIZING\Solar_Sizing_Bill_Calculator_With_AI_Backend\solar\services\quote_service.py", line 91, in generate_quote
    costs = cls._get_all_costs(system_size, panels_needed)
            ^^^^^^^^^^^^^^^^^^^^^^^^^^^^^^^^^^^^^^^^^^^^^^
  File "C:\Projects\Mustafa\NOTFINAL\SOLARSIZING\Solar_Sizing_Bill_Calculator_With_AI_Backend\solar\services\quote_service.py", line 249, in _get_all_costs
    raise AppError(
solar.middleware.error_handler.AppError: Failed to retrieve costs
ERROR 2024-12-06 03:18:05,856 inventory_service 9840 25400 Error retrieving bracket costs
Traceback (most recent call last):
  File "C:\Projects\Mustafa\NOTFINAL\SOLARSIZING\Solar_Sizing_Bill_Calculator_With_AI_Backend\venv\Lib\site-packages\django\db\backends\utils.py", line 105, in _execute
    return self.cursor.execute(sql, params)
           ^^^^^^^^^^^^^^^^^^^^^^^^^^^^^^^^
  File "C:\Projects\Mustafa\NOTFINAL\SOLARSIZING\Solar_Sizing_Bill_Calculator_With_AI_Backend\venv\Lib\site-packages\django\db\backends\sqlite3\base.py", line 354, in execute
    return super().execute(query, params)
           ^^^^^^^^^^^^^^^^^^^^^^^^^^^^^^
sqlite3.OperationalError: no such column: solar_bracketcosts.min_size

The above exception was the direct cause of the following exception:

Traceback (most recent call last):
  File "C:\Projects\Mustafa\NOTFINAL\SOLARSIZING\Solar_Sizing_Bill_Calculator_With_AI_Backend\solar\services\inventory_service.py", line 237, in get_bracket_costs
    ).first()
      ^^^^^^^
  File "C:\Projects\Mustafa\NOTFINAL\SOLARSIZING\Solar_Sizing_Bill_Calculator_With_AI_Backend\venv\Lib\site-packages\django\db\models\query.py", line 1097, in first
    for obj in queryset[:1]:
  File "C:\Projects\Mustafa\NOTFINAL\SOLARSIZING\Solar_Sizing_Bill_Calculator_With_AI_Backend\venv\Lib\site-packages\django\db\models\query.py", line 400, in __iter__
    self._fetch_all()
  File "C:\Projects\Mustafa\NOTFINAL\SOLARSIZING\Solar_Sizing_Bill_Calculator_With_AI_Backend\venv\Lib\site-packages\django\db\models\query.py", line 1928, in _fetch_all
    self._result_cache = list(self._iterable_class(self))
                         ^^^^^^^^^^^^^^^^^^^^^^^^^^^^^^^^
  File "C:\Projects\Mustafa\NOTFINAL\SOLARSIZING\Solar_Sizing_Bill_Calculator_With_AI_Backend\venv\Lib\site-packages\django\db\models\query.py", line 91, in __iter__
    results = compiler.execute_sql(
              ^^^^^^^^^^^^^^^^^^^^^
  File "C:\Projects\Mustafa\NOTFINAL\SOLARSIZING\Solar_Sizing_Bill_Calculator_With_AI_Backend\venv\Lib\site-packages\django\db\models\sql\compiler.py", line 1574, in execute_sql
    cursor.execute(sql, params)
  File "C:\Projects\Mustafa\NOTFINAL\SOLARSIZING\Solar_Sizing_Bill_Calculator_With_AI_Backend\venv\Lib\site-packages\django\db\backends\utils.py", line 122, in execute
    return super().execute(sql, params)
           ^^^^^^^^^^^^^^^^^^^^^^^^^^^^
  File "C:\Projects\Mustafa\NOTFINAL\SOLARSIZING\Solar_Sizing_Bill_Calculator_With_AI_Backend\venv\Lib\site-packages\django\db\backends\utils.py", line 79, in execute
    return self._execute_with_wrappers(
           ^^^^^^^^^^^^^^^^^^^^^^^^^^^^
  File "C:\Projects\Mustafa\NOTFINAL\SOLARSIZING\Solar_Sizing_Bill_Calculator_With_AI_Backend\venv\Lib\site-packages\django\db\backends\utils.py", line 92, in _execute_with_wrappers
    return executor(sql, params, many, context)
           ^^^^^^^^^^^^^^^^^^^^^^^^^^^^^^^^^^^^
  File "C:\Projects\Mustafa\NOTFINAL\SOLARSIZING\Solar_Sizing_Bill_Calculator_With_AI_Backend\venv\Lib\site-packages\django\db\backends\utils.py", line 100, in _execute
    with self.db.wrap_database_errors:
  File "C:\Projects\Mustafa\NOTFINAL\SOLARSIZING\Solar_Sizing_Bill_Calculator_With_AI_Backend\venv\Lib\site-packages\django\db\utils.py", line 91, in __exit__
    raise dj_exc_value.with_traceback(traceback) from exc_value
  File "C:\Projects\Mustafa\NOTFINAL\SOLARSIZING\Solar_Sizing_Bill_Calculator_With_AI_Backend\venv\Lib\site-packages\django\db\backends\utils.py", line 105, in _execute
    return self.cursor.execute(sql, params)
           ^^^^^^^^^^^^^^^^^^^^^^^^^^^^^^^^
  File "C:\Projects\Mustafa\NOTFINAL\SOLARSIZING\Solar_Sizing_Bill_Calculator_With_AI_Backend\venv\Lib\site-packages\django\db\backends\sqlite3\base.py", line 354, in execute
    return super().execute(query, params)
           ^^^^^^^^^^^^^^^^^^^^^^^^^^^^^^
django.db.utils.OperationalError: no such column: solar_bracketcosts.min_size
ERROR 2024-12-06 03:18:05,861 quote_service 9840 25400 Error calculating costs
Traceback (most recent call last):
  File "C:\Projects\Mustafa\NOTFINAL\SOLARSIZING\Solar_Sizing_Bill_Calculator_With_AI_Backend\venv\Lib\site-packages\django\db\backends\utils.py", line 105, in _execute
    return self.cursor.execute(sql, params)
           ^^^^^^^^^^^^^^^^^^^^^^^^^^^^^^^^
  File "C:\Projects\Mustafa\NOTFINAL\SOLARSIZING\Solar_Sizing_Bill_Calculator_With_AI_Backend\venv\Lib\site-packages\django\db\backends\sqlite3\base.py", line 354, in execute
    return super().execute(query, params)
           ^^^^^^^^^^^^^^^^^^^^^^^^^^^^^^
sqlite3.OperationalError: no such column: solar_bracketcosts.min_size

The above exception was the direct cause of the following exception:

Traceback (most recent call last):
  File "C:\Projects\Mustafa\NOTFINAL\SOLARSIZING\Solar_Sizing_Bill_Calculator_With_AI_Backend\solar\services\inventory_service.py", line 237, in get_bracket_costs
    ).first()
      ^^^^^^^
  File "C:\Projects\Mustafa\NOTFINAL\SOLARSIZING\Solar_Sizing_Bill_Calculator_With_AI_Backend\venv\Lib\site-packages\django\db\models\query.py", line 1097, in first
    for obj in queryset[:1]:
  File "C:\Projects\Mustafa\NOTFINAL\SOLARSIZING\Solar_Sizing_Bill_Calculator_With_AI_Backend\venv\Lib\site-packages\django\db\models\query.py", line 400, in __iter__
    self._fetch_all()
  File "C:\Projects\Mustafa\NOTFINAL\SOLARSIZING\Solar_Sizing_Bill_Calculator_With_AI_Backend\venv\Lib\site-packages\django\db\models\query.py", line 1928, in _fetch_all
    self._result_cache = list(self._iterable_class(self))
                         ^^^^^^^^^^^^^^^^^^^^^^^^^^^^^^^^
  File "C:\Projects\Mustafa\NOTFINAL\SOLARSIZING\Solar_Sizing_Bill_Calculator_With_AI_Backend\venv\Lib\site-packages\django\db\models\query.py", line 91, in __iter__
    results = compiler.execute_sql(
              ^^^^^^^^^^^^^^^^^^^^^
  File "C:\Projects\Mustafa\NOTFINAL\SOLARSIZING\Solar_Sizing_Bill_Calculator_With_AI_Backend\venv\Lib\site-packages\django\db\models\sql\compiler.py", line 1574, in execute_sql
    cursor.execute(sql, params)
  File "C:\Projects\Mustafa\NOTFINAL\SOLARSIZING\Solar_Sizing_Bill_Calculator_With_AI_Backend\venv\Lib\site-packages\django\db\backends\utils.py", line 122, in execute
    return super().execute(sql, params)
           ^^^^^^^^^^^^^^^^^^^^^^^^^^^^
  File "C:\Projects\Mustafa\NOTFINAL\SOLARSIZING\Solar_Sizing_Bill_Calculator_With_AI_Backend\venv\Lib\site-packages\django\db\backends\utils.py", line 79, in execute
    return self._execute_with_wrappers(
           ^^^^^^^^^^^^^^^^^^^^^^^^^^^^
  File "C:\Projects\Mustafa\NOTFINAL\SOLARSIZING\Solar_Sizing_Bill_Calculator_With_AI_Backend\venv\Lib\site-packages\django\db\backends\utils.py", line 92, in _execute_with_wrappers
    return executor(sql, params, many, context)
           ^^^^^^^^^^^^^^^^^^^^^^^^^^^^^^^^^^^^
  File "C:\Projects\Mustafa\NOTFINAL\SOLARSIZING\Solar_Sizing_Bill_Calculator_With_AI_Backend\venv\Lib\site-packages\django\db\backends\utils.py", line 100, in _execute
    with self.db.wrap_database_errors:
  File "C:\Projects\Mustafa\NOTFINAL\SOLARSIZING\Solar_Sizing_Bill_Calculator_With_AI_Backend\venv\Lib\site-packages\django\db\utils.py", line 91, in __exit__
    raise dj_exc_value.with_traceback(traceback) from exc_value
  File "C:\Projects\Mustafa\NOTFINAL\SOLARSIZING\Solar_Sizing_Bill_Calculator_With_AI_Backend\venv\Lib\site-packages\django\db\backends\utils.py", line 105, in _execute
    return self.cursor.execute(sql, params)
           ^^^^^^^^^^^^^^^^^^^^^^^^^^^^^^^^
  File "C:\Projects\Mustafa\NOTFINAL\SOLARSIZING\Solar_Sizing_Bill_Calculator_With_AI_Backend\venv\Lib\site-packages\django\db\backends\sqlite3\base.py", line 354, in execute
    return super().execute(query, params)
           ^^^^^^^^^^^^^^^^^^^^^^^^^^^^^^
django.db.utils.OperationalError: no such column: solar_bracketcosts.min_size

During handling of the above exception, another exception occurred:

Traceback (most recent call last):
  File "C:\Projects\Mustafa\NOTFINAL\SOLARSIZING\Solar_Sizing_Bill_Calculator_With_AI_Backend\solar\services\quote_service.py", line 228, in _get_all_costs
    bracket_costs = InventoryService.get_bracket_costs(system_size)
                    ^^^^^^^^^^^^^^^^^^^^^^^^^^^^^^^^^^^^^^^^^^^^^^^
  File "C:\Projects\Mustafa\NOTFINAL\SOLARSIZING\Solar_Sizing_Bill_Calculator_With_AI_Backend\solar\services\inventory_service.py", line 261, in get_bracket_costs
    raise AppError(
solar.middleware.error_handler.AppError: Failed to retrieve bracket costs
ERROR 2024-12-06 03:18:05,863 quote_service 9840 25400 Cost calculation failed: Failed to retrieve costs
ERROR 2024-12-06 03:18:05,863 quote_service 9840 25400 Quote generation failed with AppError: Failed to retrieve costs
ERROR 2024-12-06 03:18:05,863 quote_views 9840 25400 Error in quote generation
Traceback (most recent call last):
  File "C:\Projects\Mustafa\NOTFINAL\SOLARSIZING\Solar_Sizing_Bill_Calculator_With_AI_Backend\venv\Lib\site-packages\django\db\backends\utils.py", line 105, in _execute
    return self.cursor.execute(sql, params)
           ^^^^^^^^^^^^^^^^^^^^^^^^^^^^^^^^
  File "C:\Projects\Mustafa\NOTFINAL\SOLARSIZING\Solar_Sizing_Bill_Calculator_With_AI_Backend\venv\Lib\site-packages\django\db\backends\sqlite3\base.py", line 354, in execute
    return super().execute(query, params)
           ^^^^^^^^^^^^^^^^^^^^^^^^^^^^^^
sqlite3.OperationalError: no such column: solar_bracketcosts.min_size

The above exception was the direct cause of the following exception:

Traceback (most recent call last):
  File "C:\Projects\Mustafa\NOTFINAL\SOLARSIZING\Solar_Sizing_Bill_Calculator_With_AI_Backend\solar\services\inventory_service.py", line 237, in get_bracket_costs
    ).first()
      ^^^^^^^
  File "C:\Projects\Mustafa\NOTFINAL\SOLARSIZING\Solar_Sizing_Bill_Calculator_With_AI_Backend\venv\Lib\site-packages\django\db\models\query.py", line 1097, in first
    for obj in queryset[:1]:
  File "C:\Projects\Mustafa\NOTFINAL\SOLARSIZING\Solar_Sizing_Bill_Calculator_With_AI_Backend\venv\Lib\site-packages\django\db\models\query.py", line 400, in __iter__
    self._fetch_all()
  File "C:\Projects\Mustafa\NOTFINAL\SOLARSIZING\Solar_Sizing_Bill_Calculator_With_AI_Backend\venv\Lib\site-packages\django\db\models\query.py", line 1928, in _fetch_all
    self._result_cache = list(self._iterable_class(self))
                         ^^^^^^^^^^^^^^^^^^^^^^^^^^^^^^^^
  File "C:\Projects\Mustafa\NOTFINAL\SOLARSIZING\Solar_Sizing_Bill_Calculator_With_AI_Backend\venv\Lib\site-packages\django\db\models\query.py", line 91, in __iter__
    results = compiler.execute_sql(
              ^^^^^^^^^^^^^^^^^^^^^
  File "C:\Projects\Mustafa\NOTFINAL\SOLARSIZING\Solar_Sizing_Bill_Calculator_With_AI_Backend\venv\Lib\site-packages\django\db\models\sql\compiler.py", line 1574, in execute_sql
    cursor.execute(sql, params)
  File "C:\Projects\Mustafa\NOTFINAL\SOLARSIZING\Solar_Sizing_Bill_Calculator_With_AI_Backend\venv\Lib\site-packages\django\db\backends\utils.py", line 122, in execute
    return super().execute(sql, params)
           ^^^^^^^^^^^^^^^^^^^^^^^^^^^^
  File "C:\Projects\Mustafa\NOTFINAL\SOLARSIZING\Solar_Sizing_Bill_Calculator_With_AI_Backend\venv\Lib\site-packages\django\db\backends\utils.py", line 79, in execute
    return self._execute_with_wrappers(
           ^^^^^^^^^^^^^^^^^^^^^^^^^^^^
  File "C:\Projects\Mustafa\NOTFINAL\SOLARSIZING\Solar_Sizing_Bill_Calculator_With_AI_Backend\venv\Lib\site-packages\django\db\backends\utils.py", line 92, in _execute_with_wrappers
    return executor(sql, params, many, context)
           ^^^^^^^^^^^^^^^^^^^^^^^^^^^^^^^^^^^^
  File "C:\Projects\Mustafa\NOTFINAL\SOLARSIZING\Solar_Sizing_Bill_Calculator_With_AI_Backend\venv\Lib\site-packages\django\db\backends\utils.py", line 100, in _execute
    with self.db.wrap_database_errors:
  File "C:\Projects\Mustafa\NOTFINAL\SOLARSIZING\Solar_Sizing_Bill_Calculator_With_AI_Backend\venv\Lib\site-packages\django\db\utils.py", line 91, in __exit__
    raise dj_exc_value.with_traceback(traceback) from exc_value
  File "C:\Projects\Mustafa\NOTFINAL\SOLARSIZING\Solar_Sizing_Bill_Calculator_With_AI_Backend\venv\Lib\site-packages\django\db\backends\utils.py", line 105, in _execute
    return self.cursor.execute(sql, params)
           ^^^^^^^^^^^^^^^^^^^^^^^^^^^^^^^^
  File "C:\Projects\Mustafa\NOTFINAL\SOLARSIZING\Solar_Sizing_Bill_Calculator_With_AI_Backend\venv\Lib\site-packages\django\db\backends\sqlite3\base.py", line 354, in execute
    return super().execute(query, params)
           ^^^^^^^^^^^^^^^^^^^^^^^^^^^^^^
django.db.utils.OperationalError: no such column: solar_bracketcosts.min_size

During handling of the above exception, another exception occurred:

Traceback (most recent call last):
  File "C:\Projects\Mustafa\NOTFINAL\SOLARSIZING\Solar_Sizing_Bill_Calculator_With_AI_Backend\solar\services\quote_service.py", line 228, in _get_all_costs
    bracket_costs = InventoryService.get_bracket_costs(system_size)
                    ^^^^^^^^^^^^^^^^^^^^^^^^^^^^^^^^^^^^^^^^^^^^^^^
  File "C:\Projects\Mustafa\NOTFINAL\SOLARSIZING\Solar_Sizing_Bill_Calculator_With_AI_Backend\solar\services\inventory_service.py", line 261, in get_bracket_costs
    raise AppError(
solar.middleware.error_handler.AppError: Failed to retrieve bracket costs

During handling of the above exception, another exception occurred:

Traceback (most recent call last):
  File "C:\Projects\Mustafa\NOTFINAL\SOLARSIZING\Solar_Sizing_Bill_Calculator_With_AI_Backend\solar\views\quote_views.py", line 46, in post
    quote_data = QuoteService.generate_quote(request.data)
                 ^^^^^^^^^^^^^^^^^^^^^^^^^^^^^^^^^^^^^^^^^
  File "C:\Projects\Mustafa\NOTFINAL\SOLARSIZING\Solar_Sizing_Bill_Calculator_With_AI_Backend\solar\services\quote_service.py", line 91, in generate_quote
    costs = cls._get_all_costs(system_size, panels_needed)
            ^^^^^^^^^^^^^^^^^^^^^^^^^^^^^^^^^^^^^^^^^^^^^^
  File "C:\Projects\Mustafa\NOTFINAL\SOLARSIZING\Solar_Sizing_Bill_Calculator_With_AI_Backend\solar\services\quote_service.py", line 249, in _get_all_costs
    raise AppError(
solar.middleware.error_handler.AppError: Failed to retrieve costs
ERROR 2024-12-06 03:29:51,240 quote_service 11472 25508 Component selection failed: No default panel configured
ERROR 2024-12-06 03:29:51,240 quote_service 11472 25508 Quote generation failed with AppError: No default panel configured
ERROR 2024-12-06 03:29:51,240 quote_views 11472 25508 Error in quote generation
Traceback (most recent call last):
  File "C:\Projects\Mustafa\NOTFINAL\SOLARSIZING\Solar_Sizing_Bill_Calculator_With_AI_Backend\solar\views\quote_views.py", line 46, in post
    quote_data = QuoteService.generate_quote(request.data)
                 ^^^^^^^^^^^^^^^^^^^^^^^^^^^^^^^^^^^^^^^^^
  File "C:\Projects\Mustafa\NOTFINAL\SOLARSIZING\Solar_Sizing_Bill_Calculator_With_AI_Backend\solar\services\quote_service.py", line 79, in generate_quote
    panel = cls._get_default_panel()
            ^^^^^^^^^^^^^^^^^^^^^^^^
  File "C:\Projects\Mustafa\NOTFINAL\SOLARSIZING\Solar_Sizing_Bill_Calculator_With_AI_Backend\solar\services\quote_service.py", line 170, in _get_default_panel
    raise AppError(
solar.middleware.error_handler.AppError: No default panel configured
ERROR 2024-12-06 03:43:44,384 inventory_service 22220 2676 Error retrieving bracket costs
Traceback (most recent call last):
  File "C:\Projects\Mustafa\NOTFINAL\SOLARSIZING\Solar_Sizing_Bill_Calculator_With_AI_Backend\venv\Lib\site-packages\django\db\backends\utils.py", line 105, in _execute
    return self.cursor.execute(sql, params)
           ^^^^^^^^^^^^^^^^^^^^^^^^^^^^^^^^
  File "C:\Projects\Mustafa\NOTFINAL\SOLARSIZING\Solar_Sizing_Bill_Calculator_With_AI_Backend\venv\Lib\site-packages\django\db\backends\sqlite3\base.py", line 354, in execute
    return super().execute(query, params)
           ^^^^^^^^^^^^^^^^^^^^^^^^^^^^^^
sqlite3.OperationalError: no such column: solar_bracketcosts.min_size

The above exception was the direct cause of the following exception:

Traceback (most recent call last):
  File "C:\Projects\Mustafa\NOTFINAL\SOLARSIZING\Solar_Sizing_Bill_Calculator_With_AI_Backend\solar\services\inventory_service.py", line 260, in get_bracket_costs
    ).first()
      ^^^^^^^
  File "C:\Projects\Mustafa\NOTFINAL\SOLARSIZING\Solar_Sizing_Bill_Calculator_With_AI_Backend\venv\Lib\site-packages\django\db\models\query.py", line 1097, in first
    for obj in queryset[:1]:
  File "C:\Projects\Mustafa\NOTFINAL\SOLARSIZING\Solar_Sizing_Bill_Calculator_With_AI_Backend\venv\Lib\site-packages\django\db\models\query.py", line 400, in __iter__
    self._fetch_all()
  File "C:\Projects\Mustafa\NOTFINAL\SOLARSIZING\Solar_Sizing_Bill_Calculator_With_AI_Backend\venv\Lib\site-packages\django\db\models\query.py", line 1928, in _fetch_all
    self._result_cache = list(self._iterable_class(self))
                         ^^^^^^^^^^^^^^^^^^^^^^^^^^^^^^^^
  File "C:\Projects\Mustafa\NOTFINAL\SOLARSIZING\Solar_Sizing_Bill_Calculator_With_AI_Backend\venv\Lib\site-packages\django\db\models\query.py", line 91, in __iter__
    results = compiler.execute_sql(
              ^^^^^^^^^^^^^^^^^^^^^
  File "C:\Projects\Mustafa\NOTFINAL\SOLARSIZING\Solar_Sizing_Bill_Calculator_With_AI_Backend\venv\Lib\site-packages\django\db\models\sql\compiler.py", line 1574, in execute_sql
    cursor.execute(sql, params)
  File "C:\Projects\Mustafa\NOTFINAL\SOLARSIZING\Solar_Sizing_Bill_Calculator_With_AI_Backend\venv\Lib\site-packages\django\db\backends\utils.py", line 122, in execute
    return super().execute(sql, params)
           ^^^^^^^^^^^^^^^^^^^^^^^^^^^^
  File "C:\Projects\Mustafa\NOTFINAL\SOLARSIZING\Solar_Sizing_Bill_Calculator_With_AI_Backend\venv\Lib\site-packages\django\db\backends\utils.py", line 79, in execute
    return self._execute_with_wrappers(
           ^^^^^^^^^^^^^^^^^^^^^^^^^^^^
  File "C:\Projects\Mustafa\NOTFINAL\SOLARSIZING\Solar_Sizing_Bill_Calculator_With_AI_Backend\venv\Lib\site-packages\django\db\backends\utils.py", line 92, in _execute_with_wrappers
    return executor(sql, params, many, context)
           ^^^^^^^^^^^^^^^^^^^^^^^^^^^^^^^^^^^^
  File "C:\Projects\Mustafa\NOTFINAL\SOLARSIZING\Solar_Sizing_Bill_Calculator_With_AI_Backend\venv\Lib\site-packages\django\db\backends\utils.py", line 100, in _execute
    with self.db.wrap_database_errors:
  File "C:\Projects\Mustafa\NOTFINAL\SOLARSIZING\Solar_Sizing_Bill_Calculator_With_AI_Backend\venv\Lib\site-packages\django\db\utils.py", line 91, in __exit__
    raise dj_exc_value.with_traceback(traceback) from exc_value
  File "C:\Projects\Mustafa\NOTFINAL\SOLARSIZING\Solar_Sizing_Bill_Calculator_With_AI_Backend\venv\Lib\site-packages\django\db\backends\utils.py", line 105, in _execute
    return self.cursor.execute(sql, params)
           ^^^^^^^^^^^^^^^^^^^^^^^^^^^^^^^^
  File "C:\Projects\Mustafa\NOTFINAL\SOLARSIZING\Solar_Sizing_Bill_Calculator_With_AI_Backend\venv\Lib\site-packages\django\db\backends\sqlite3\base.py", line 354, in execute
    return super().execute(query, params)
           ^^^^^^^^^^^^^^^^^^^^^^^^^^^^^^
django.db.utils.OperationalError: no such column: solar_bracketcosts.min_size
ERROR 2024-12-06 03:43:44,390 quote_service 22220 2676 Error calculating costs
Traceback (most recent call last):
  File "C:\Projects\Mustafa\NOTFINAL\SOLARSIZING\Solar_Sizing_Bill_Calculator_With_AI_Backend\venv\Lib\site-packages\django\db\backends\utils.py", line 105, in _execute
    return self.cursor.execute(sql, params)
           ^^^^^^^^^^^^^^^^^^^^^^^^^^^^^^^^
  File "C:\Projects\Mustafa\NOTFINAL\SOLARSIZING\Solar_Sizing_Bill_Calculator_With_AI_Backend\venv\Lib\site-packages\django\db\backends\sqlite3\base.py", line 354, in execute
    return super().execute(query, params)
           ^^^^^^^^^^^^^^^^^^^^^^^^^^^^^^
sqlite3.OperationalError: no such column: solar_bracketcosts.min_size

The above exception was the direct cause of the following exception:

Traceback (most recent call last):
  File "C:\Projects\Mustafa\NOTFINAL\SOLARSIZING\Solar_Sizing_Bill_Calculator_With_AI_Backend\solar\services\inventory_service.py", line 260, in get_bracket_costs
    ).first()
      ^^^^^^^
  File "C:\Projects\Mustafa\NOTFINAL\SOLARSIZING\Solar_Sizing_Bill_Calculator_With_AI_Backend\venv\Lib\site-packages\django\db\models\query.py", line 1097, in first
    for obj in queryset[:1]:
  File "C:\Projects\Mustafa\NOTFINAL\SOLARSIZING\Solar_Sizing_Bill_Calculator_With_AI_Backend\venv\Lib\site-packages\django\db\models\query.py", line 400, in __iter__
    self._fetch_all()
  File "C:\Projects\Mustafa\NOTFINAL\SOLARSIZING\Solar_Sizing_Bill_Calculator_With_AI_Backend\venv\Lib\site-packages\django\db\models\query.py", line 1928, in _fetch_all
    self._result_cache = list(self._iterable_class(self))
                         ^^^^^^^^^^^^^^^^^^^^^^^^^^^^^^^^
  File "C:\Projects\Mustafa\NOTFINAL\SOLARSIZING\Solar_Sizing_Bill_Calculator_With_AI_Backend\venv\Lib\site-packages\django\db\models\query.py", line 91, in __iter__
    results = compiler.execute_sql(
              ^^^^^^^^^^^^^^^^^^^^^
  File "C:\Projects\Mustafa\NOTFINAL\SOLARSIZING\Solar_Sizing_Bill_Calculator_With_AI_Backend\venv\Lib\site-packages\django\db\models\sql\compiler.py", line 1574, in execute_sql
    cursor.execute(sql, params)
  File "C:\Projects\Mustafa\NOTFINAL\SOLARSIZING\Solar_Sizing_Bill_Calculator_With_AI_Backend\venv\Lib\site-packages\django\db\backends\utils.py", line 122, in execute
    return super().execute(sql, params)
           ^^^^^^^^^^^^^^^^^^^^^^^^^^^^
  File "C:\Projects\Mustafa\NOTFINAL\SOLARSIZING\Solar_Sizing_Bill_Calculator_With_AI_Backend\venv\Lib\site-packages\django\db\backends\utils.py", line 79, in execute
    return self._execute_with_wrappers(
           ^^^^^^^^^^^^^^^^^^^^^^^^^^^^
  File "C:\Projects\Mustafa\NOTFINAL\SOLARSIZING\Solar_Sizing_Bill_Calculator_With_AI_Backend\venv\Lib\site-packages\django\db\backends\utils.py", line 92, in _execute_with_wrappers
    return executor(sql, params, many, context)
           ^^^^^^^^^^^^^^^^^^^^^^^^^^^^^^^^^^^^
  File "C:\Projects\Mustafa\NOTFINAL\SOLARSIZING\Solar_Sizing_Bill_Calculator_With_AI_Backend\venv\Lib\site-packages\django\db\backends\utils.py", line 100, in _execute
    with self.db.wrap_database_errors:
  File "C:\Projects\Mustafa\NOTFINAL\SOLARSIZING\Solar_Sizing_Bill_Calculator_With_AI_Backend\venv\Lib\site-packages\django\db\utils.py", line 91, in __exit__
    raise dj_exc_value.with_traceback(traceback) from exc_value
  File "C:\Projects\Mustafa\NOTFINAL\SOLARSIZING\Solar_Sizing_Bill_Calculator_With_AI_Backend\venv\Lib\site-packages\django\db\backends\utils.py", line 105, in _execute
    return self.cursor.execute(sql, params)
           ^^^^^^^^^^^^^^^^^^^^^^^^^^^^^^^^
  File "C:\Projects\Mustafa\NOTFINAL\SOLARSIZING\Solar_Sizing_Bill_Calculator_With_AI_Backend\venv\Lib\site-packages\django\db\backends\sqlite3\base.py", line 354, in execute
    return super().execute(query, params)
           ^^^^^^^^^^^^^^^^^^^^^^^^^^^^^^
django.db.utils.OperationalError: no such column: solar_bracketcosts.min_size

During handling of the above exception, another exception occurred:

Traceback (most recent call last):
  File "C:\Projects\Mustafa\NOTFINAL\SOLARSIZING\Solar_Sizing_Bill_Calculator_With_AI_Backend\solar\services\quote_service.py", line 228, in _get_all_costs
    bracket_costs = InventoryService.get_bracket_costs(system_size)
                    ^^^^^^^^^^^^^^^^^^^^^^^^^^^^^^^^^^^^^^^^^^^^^^^
  File "C:\Projects\Mustafa\NOTFINAL\SOLARSIZING\Solar_Sizing_Bill_Calculator_With_AI_Backend\solar\services\inventory_service.py", line 284, in get_bracket_costs
    raise AppError(
solar.middleware.error_handler.AppError: Failed to retrieve bracket costs
ERROR 2024-12-06 03:43:44,391 quote_service 22220 2676 Cost calculation failed: Failed to retrieve costs
ERROR 2024-12-06 03:43:44,391 quote_service 22220 2676 Quote generation failed with AppError: Failed to retrieve costs
ERROR 2024-12-06 03:43:44,392 quote_views 22220 2676 Error in quote generation
Traceback (most recent call last):
  File "C:\Projects\Mustafa\NOTFINAL\SOLARSIZING\Solar_Sizing_Bill_Calculator_With_AI_Backend\venv\Lib\site-packages\django\db\backends\utils.py", line 105, in _execute
    return self.cursor.execute(sql, params)
           ^^^^^^^^^^^^^^^^^^^^^^^^^^^^^^^^
  File "C:\Projects\Mustafa\NOTFINAL\SOLARSIZING\Solar_Sizing_Bill_Calculator_With_AI_Backend\venv\Lib\site-packages\django\db\backends\sqlite3\base.py", line 354, in execute
    return super().execute(query, params)
           ^^^^^^^^^^^^^^^^^^^^^^^^^^^^^^
sqlite3.OperationalError: no such column: solar_bracketcosts.min_size

The above exception was the direct cause of the following exception:

Traceback (most recent call last):
  File "C:\Projects\Mustafa\NOTFINAL\SOLARSIZING\Solar_Sizing_Bill_Calculator_With_AI_Backend\solar\services\inventory_service.py", line 260, in get_bracket_costs
    ).first()
      ^^^^^^^
  File "C:\Projects\Mustafa\NOTFINAL\SOLARSIZING\Solar_Sizing_Bill_Calculator_With_AI_Backend\venv\Lib\site-packages\django\db\models\query.py", line 1097, in first
    for obj in queryset[:1]:
  File "C:\Projects\Mustafa\NOTFINAL\SOLARSIZING\Solar_Sizing_Bill_Calculator_With_AI_Backend\venv\Lib\site-packages\django\db\models\query.py", line 400, in __iter__
    self._fetch_all()
  File "C:\Projects\Mustafa\NOTFINAL\SOLARSIZING\Solar_Sizing_Bill_Calculator_With_AI_Backend\venv\Lib\site-packages\django\db\models\query.py", line 1928, in _fetch_all
    self._result_cache = list(self._iterable_class(self))
                         ^^^^^^^^^^^^^^^^^^^^^^^^^^^^^^^^
  File "C:\Projects\Mustafa\NOTFINAL\SOLARSIZING\Solar_Sizing_Bill_Calculator_With_AI_Backend\venv\Lib\site-packages\django\db\models\query.py", line 91, in __iter__
    results = compiler.execute_sql(
              ^^^^^^^^^^^^^^^^^^^^^
  File "C:\Projects\Mustafa\NOTFINAL\SOLARSIZING\Solar_Sizing_Bill_Calculator_With_AI_Backend\venv\Lib\site-packages\django\db\models\sql\compiler.py", line 1574, in execute_sql
    cursor.execute(sql, params)
  File "C:\Projects\Mustafa\NOTFINAL\SOLARSIZING\Solar_Sizing_Bill_Calculator_With_AI_Backend\venv\Lib\site-packages\django\db\backends\utils.py", line 122, in execute
    return super().execute(sql, params)
           ^^^^^^^^^^^^^^^^^^^^^^^^^^^^
  File "C:\Projects\Mustafa\NOTFINAL\SOLARSIZING\Solar_Sizing_Bill_Calculator_With_AI_Backend\venv\Lib\site-packages\django\db\backends\utils.py", line 79, in execute
    return self._execute_with_wrappers(
           ^^^^^^^^^^^^^^^^^^^^^^^^^^^^
  File "C:\Projects\Mustafa\NOTFINAL\SOLARSIZING\Solar_Sizing_Bill_Calculator_With_AI_Backend\venv\Lib\site-packages\django\db\backends\utils.py", line 92, in _execute_with_wrappers
    return executor(sql, params, many, context)
           ^^^^^^^^^^^^^^^^^^^^^^^^^^^^^^^^^^^^
  File "C:\Projects\Mustafa\NOTFINAL\SOLARSIZING\Solar_Sizing_Bill_Calculator_With_AI_Backend\venv\Lib\site-packages\django\db\backends\utils.py", line 100, in _execute
    with self.db.wrap_database_errors:
  File "C:\Projects\Mustafa\NOTFINAL\SOLARSIZING\Solar_Sizing_Bill_Calculator_With_AI_Backend\venv\Lib\site-packages\django\db\utils.py", line 91, in __exit__
    raise dj_exc_value.with_traceback(traceback) from exc_value
  File "C:\Projects\Mustafa\NOTFINAL\SOLARSIZING\Solar_Sizing_Bill_Calculator_With_AI_Backend\venv\Lib\site-packages\django\db\backends\utils.py", line 105, in _execute
    return self.cursor.execute(sql, params)
           ^^^^^^^^^^^^^^^^^^^^^^^^^^^^^^^^
  File "C:\Projects\Mustafa\NOTFINAL\SOLARSIZING\Solar_Sizing_Bill_Calculator_With_AI_Backend\venv\Lib\site-packages\django\db\backends\sqlite3\base.py", line 354, in execute
    return super().execute(query, params)
           ^^^^^^^^^^^^^^^^^^^^^^^^^^^^^^
django.db.utils.OperationalError: no such column: solar_bracketcosts.min_size

During handling of the above exception, another exception occurred:

Traceback (most recent call last):
  File "C:\Projects\Mustafa\NOTFINAL\SOLARSIZING\Solar_Sizing_Bill_Calculator_With_AI_Backend\solar\services\quote_service.py", line 228, in _get_all_costs
    bracket_costs = InventoryService.get_bracket_costs(system_size)
                    ^^^^^^^^^^^^^^^^^^^^^^^^^^^^^^^^^^^^^^^^^^^^^^^
  File "C:\Projects\Mustafa\NOTFINAL\SOLARSIZING\Solar_Sizing_Bill_Calculator_With_AI_Backend\solar\services\inventory_service.py", line 284, in get_bracket_costs
    raise AppError(
solar.middleware.error_handler.AppError: Failed to retrieve bracket costs

During handling of the above exception, another exception occurred:

Traceback (most recent call last):
  File "C:\Projects\Mustafa\NOTFINAL\SOLARSIZING\Solar_Sizing_Bill_Calculator_With_AI_Backend\solar\views\quote_views.py", line 46, in post
    quote_data = QuoteService.generate_quote(request.data)
                 ^^^^^^^^^^^^^^^^^^^^^^^^^^^^^^^^^^^^^^^^^
  File "C:\Projects\Mustafa\NOTFINAL\SOLARSIZING\Solar_Sizing_Bill_Calculator_With_AI_Backend\solar\services\quote_service.py", line 91, in generate_quote
    costs = cls._get_all_costs(system_size, panels_needed)
            ^^^^^^^^^^^^^^^^^^^^^^^^^^^^^^^^^^^^^^^^^^^^^^
  File "C:\Projects\Mustafa\NOTFINAL\SOLARSIZING\Solar_Sizing_Bill_Calculator_With_AI_Backend\solar\services\quote_service.py", line 249, in _get_all_costs
    raise AppError(
solar.middleware.error_handler.AppError: Failed to retrieve costs
ERROR 2025-02-27 00:35:05,610 quote_views 27356 14744 Error in quote generation
Traceback (most recent call last):
  File "D:\Projects\Solar_Sizing_Bill_Calculator_With_AI_Backend\solar\views\quote_views.py", line 50, in post
    generate_invoice(quote_data)
    ~~~~~~~~~~~~~~~~^^^^^^^^^^^^
TypeError: generate_invoice() missing 14 required positional arguments: 'panel_amount', 'panel_power', 'price_of_inverter', 'brand_of_inverter', 'price_of_panels', 'netmetering_costs', 'installation_costs', 'cabling_costs', 'structure_costs', 'electrical_and_mechanical_costs', 'total_cost', 'customer_name', 'customer_address', and 'customer_contact'
ERROR 2025-02-27 00:35:37,862 quote_views 27356 14744 Error in quote generation
Traceback (most recent call last):
  File "D:\Projects\Solar_Sizing_Bill_Calculator_With_AI_Backend\solar\views\quote_views.py", line 50, in post
    generate_invoice(quote_data)
    ~~~~~~~~~~~~~~~~^^^^^^^^^^^^
TypeError: generate_invoice() missing 14 required positional arguments: 'panel_amount', 'panel_power', 'price_of_inverter', 'brand_of_inverter', 'price_of_panels', 'netmetering_costs', 'installation_costs', 'cabling_costs', 'structure_costs', 'electrical_and_mechanical_costs', 'total_cost', 'customer_name', 'customer_address', and 'customer_contact'
ERROR 2025-02-27 01:09:05,897 quote_service 25008 10388 Unexpected error in quote generation
Traceback (most recent call last):
  File "D:\Projects\Solar_Sizing_Bill_Calculator_With_AI_Backend\solar\services\quote_service.py", line 115, in generate_quote
    'price': float(panel.price) * panels_needed * panel.power
             ~~~~~~~~~~~~~~~~~~~~~~~~~~~~~~~~~~~^~~~~~~~~~~~~
TypeError: unsupported operand type(s) for *: 'float' and 'decimal.Decimal'
ERROR 2025-02-27 01:09:05,898 quote_views 25008 10388 Error in quote generation
Traceback (most recent call last):
  File "D:\Projects\Solar_Sizing_Bill_Calculator_With_AI_Backend\solar\services\quote_service.py", line 115, in generate_quote
    'price': float(panel.price) * panels_needed * panel.power
             ~~~~~~~~~~~~~~~~~~~~~~~~~~~~~~~~~~~^~~~~~~~~~~~~
TypeError: unsupported operand type(s) for *: 'float' and 'decimal.Decimal'

During handling of the above exception, another exception occurred:

Traceback (most recent call last):
  File "D:\Projects\Solar_Sizing_Bill_Calculator_With_AI_Backend\solar\views\quote_views.py", line 46, in post
    quote_data = QuoteService.generate_quote(request.data)
  File "D:\Projects\Solar_Sizing_Bill_Calculator_With_AI_Backend\solar\services\quote_service.py", line 156, in generate_quote
    raise AppError(
    ...<3 lines>...
    )
solar.middleware.error_handler.AppError: Failed to generate quote
INFO 2025-02-27 01:11:31,429 quote_views 3332 16808 Raw quote generation request data: {'reference_number': '04151722337322', 'units_consumed': 388, 'amount': 25836, 'total_yearly_units': 10020, 'customer_name': 'MUHAMMAD ARIF', 'issue_date': '2025-02-14', 'due_date': '2025-02-23'}
INFO 2025-02-27 01:11:31,429 quote_views 3332 16808 Request content type: application/json
INFO 2025-02-27 01:11:31,429 quote_views 3332 16808 Field units_consumed: value=388, type=<class 'int'>
INFO 2025-02-27 01:11:31,429 quote_views 3332 16808 Field amount: value=25836, type=<class 'int'>
INFO 2025-02-27 01:11:31,429 quote_views 3332 16808 Field total_yearly_units: value=10020, type=<class 'int'>
INFO 2025-02-27 01:11:31,429 quote_views 3332 16808 Converted values - units: 388.0, amount: 25836.0, yearly: 10020.0
INFO 2025-02-27 01:11:31,429 quote_views 3332 16808 Passing to quote service:
INFO 2025-02-27 01:11:31,429 quote_service 3332 16808 === Starting Quote Generation ===
INFO 2025-02-27 01:11:31,429 quote_service 3332 16808 Received bill data: {'reference_number': '04151722337322', 'units_consumed': 388, 'amount': 25836, 'total_yearly_units': 10020, 'customer_name': 'MUHAMMAD ARIF', 'issue_date': '2025-02-14', 'due_date': '2025-02-23'}
INFO 2025-02-27 01:11:31,430 quote_service 3332 16808 Sanitized data: {'reference_number': '04151722337322', 'units_consumed': 388.0, 'amount': 25836.0, 'total_yearly_units': 10020.0, 'customer_name': 'MUHAMMAD ARIF', 'customer_address': '', 'issue_date': '2025-02-14', 'due_date': '2025-02-23'}
INFO 2025-02-27 01:11:31,430 quote_service 3332 16808 Calculated system size: 13kW
INFO 2025-02-27 01:11:31,433 quote_service 3332 16808 Components selected - Panel: Canada Solar, Count: 23, Inverter: MaxPower
INFO 2025-02-27 01:11:31,433 quote_service 3332 16808 Calculating costs for 13kW system with 23 panels
INFO 2025-02-27 01:11:31,434 inventory_service 3332 16808 Fetching bracket costs for system size: 13kW
INFO 2025-02-27 01:11:31,435 inventory_service 3332 16808 Retrieved costs: {'dc_cable': 15000.0, 'ac_cable': 10000.0, 'accessories': 20000.0}
INFO 2025-02-27 01:11:31,435 quote_service 3332 16808 Retrieved bracket costs: {'dc_cable': 15000.0, 'ac_cable': 10000.0, 'accessories': 20000.0}
INFO 2025-02-27 01:11:31,435 quote_service 3332 16808 Final calculated costs: {'net_metering': 250000.0, 'installation': 105300.0, 'frame': 70200.0, 'labor': 104.0, 'dc_cable': 15000.0, 'ac_cable': 10000.0, 'accessories': 20000.0, 'transport': 200.0}
INFO 2025-02-27 01:11:31,436 quote_service 3332 16808 Calculated costs: {'net_metering': 250000.0, 'installation': 105300.0, 'frame': 70200.0, 'labor': 104.0, 'dc_cable': 15000.0, 'ac_cable': 10000.0, 'accessories': 20000.0, 'transport': 200.0}
ERROR 2025-02-27 01:11:31,436 quote_service 3332 16808 Unexpected error in quote generation
Traceback (most recent call last):
  File "D:\Projects\Solar_Sizing_Bill_Calculator_With_AI_Backend\solar\services\quote_service.py", line 115, in generate_quote
    'price': float(panel.price) * panels_needed * panel.power
             ~~~~~~~~~~~~~~~~~~~~~~~~~~~~~~~~~~~^~~~~~~~~~~~~
TypeError: unsupported operand type(s) for *: 'float' and 'decimal.Decimal'
ERROR 2025-02-27 01:11:31,437 quote_views 3332 16808 Error in quote generation
Traceback (most recent call last):
  File "D:\Projects\Solar_Sizing_Bill_Calculator_With_AI_Backend\solar\services\quote_service.py", line 115, in generate_quote
    'price': float(panel.price) * panels_needed * panel.power
             ~~~~~~~~~~~~~~~~~~~~~~~~~~~~~~~~~~~^~~~~~~~~~~~~
TypeError: unsupported operand type(s) for *: 'float' and 'decimal.Decimal'

During handling of the above exception, another exception occurred:

Traceback (most recent call last):
  File "D:\Projects\Solar_Sizing_Bill_Calculator_With_AI_Backend\solar\views\quote_views.py", line 46, in post
    quote_data = QuoteService.generate_quote(request.data)
  File "D:\Projects\Solar_Sizing_Bill_Calculator_With_AI_Backend\solar\services\quote_service.py", line 156, in generate_quote
    raise AppError(
    ...<3 lines>...
    )
solar.middleware.error_handler.AppError: Failed to generate quote
INFO 2025-02-27 01:11:52,355 quote_views 27204 18400 Raw quote generation request data: {'reference_number': '04151722337322', 'units_consumed': 388, 'amount': 25836, 'total_yearly_units': 10020, 'customer_name': 'MUHAMMAD ARIF', 'issue_date': '2025-02-14', 'due_date': '2025-02-23'}
INFO 2025-02-27 01:11:52,355 quote_views 27204 18400 Request content type: application/json
INFO 2025-02-27 01:11:52,355 quote_views 27204 18400 Field units_consumed: value=388, type=<class 'int'>
INFO 2025-02-27 01:11:52,356 quote_views 27204 18400 Field amount: value=25836, type=<class 'int'>
INFO 2025-02-27 01:11:52,356 quote_views 27204 18400 Field total_yearly_units: value=10020, type=<class 'int'>
INFO 2025-02-27 01:11:52,356 quote_views 27204 18400 Converted values - units: 388.0, amount: 25836.0, yearly: 10020.0
INFO 2025-02-27 01:11:52,356 quote_views 27204 18400 Passing to quote service:
INFO 2025-02-27 01:11:52,356 quote_service 27204 18400 === Starting Quote Generation ===
INFO 2025-02-27 01:11:52,356 quote_service 27204 18400 Received bill data: {'reference_number': '04151722337322', 'units_consumed': 388, 'amount': 25836, 'total_yearly_units': 10020, 'customer_name': 'MUHAMMAD ARIF', 'issue_date': '2025-02-14', 'due_date': '2025-02-23'}
INFO 2025-02-27 01:11:52,356 quote_service 27204 18400 Sanitized data: {'reference_number': '04151722337322', 'units_consumed': 388.0, 'amount': 25836.0, 'total_yearly_units': 10020.0, 'customer_name': 'MUHAMMAD ARIF', 'customer_address': '', 'issue_date': '2025-02-14', 'due_date': '2025-02-23'}
INFO 2025-02-27 01:11:52,356 quote_service 27204 18400 Calculated system size: 13kW
INFO 2025-02-27 01:11:52,361 quote_service 27204 18400 Components selected - Panel: Canada Solar, Count: 23, Inverter: MaxPower
INFO 2025-02-27 01:11:52,362 quote_service 27204 18400 Calculating costs for 13kW system with 23 panels
INFO 2025-02-27 01:11:52,363 inventory_service 27204 18400 Fetching bracket costs for system size: 13kW
INFO 2025-02-27 01:11:52,364 inventory_service 27204 18400 Retrieved costs: {'dc_cable': 15000.0, 'ac_cable': 10000.0, 'accessories': 20000.0}
INFO 2025-02-27 01:11:52,364 quote_service 27204 18400 Retrieved bracket costs: {'dc_cable': 15000.0, 'ac_cable': 10000.0, 'accessories': 20000.0}
INFO 2025-02-27 01:11:52,365 quote_service 27204 18400 Final calculated costs: {'net_metering': 250000.0, 'installation': 105300.0, 'frame': 70200.0, 'labor': 104.0, 'dc_cable': 15000.0, 'ac_cable': 10000.0, 'accessories': 20000.0, 'transport': 200.0}
INFO 2025-02-27 01:11:52,365 quote_service 27204 18400 Calculated costs: {'net_metering': 250000.0, 'installation': 105300.0, 'frame': 70200.0, 'labor': 104.0, 'dc_cable': 15000.0, 'ac_cable': 10000.0, 'accessories': 20000.0, 'transport': 200.0}
ERROR 2025-02-27 01:11:52,365 quote_service 27204 18400 Unexpected error in quote generation
Traceback (most recent call last):
  File "D:\Projects\Solar_Sizing_Bill_Calculator_With_AI_Backend\solar\services\quote_service.py", line 115, in generate_quote
    'price': float(panel.price) * panels_needed * panel.power
             ~~~~~~~~~~~~~~~~~~~~~~~~~~~~~~~~~~~^~~~~~~~~~~~~
TypeError: unsupported operand type(s) for *: 'float' and 'decimal.Decimal'
ERROR 2025-02-27 01:11:52,366 quote_views 27204 18400 Error in quote generation
Traceback (most recent call last):
  File "D:\Projects\Solar_Sizing_Bill_Calculator_With_AI_Backend\solar\services\quote_service.py", line 115, in generate_quote
    'price': float(panel.price) * panels_needed * panel.power
             ~~~~~~~~~~~~~~~~~~~~~~~~~~~~~~~~~~~^~~~~~~~~~~~~
TypeError: unsupported operand type(s) for *: 'float' and 'decimal.Decimal'

During handling of the above exception, another exception occurred:

Traceback (most recent call last):
  File "D:\Projects\Solar_Sizing_Bill_Calculator_With_AI_Backend\solar\views\quote_views.py", line 46, in post
    quote_data = QuoteService.generate_quote(request.data)
  File "D:\Projects\Solar_Sizing_Bill_Calculator_With_AI_Backend\solar\services\quote_service.py", line 156, in generate_quote
    raise AppError(
    ...<3 lines>...
    )
solar.middleware.error_handler.AppError: Failed to generate quote
INFO 2025-02-27 01:13:21,018 quote_views 1992 1476 Raw quote generation request data: {'reference_number': '04151722337322', 'units_consumed': 388, 'amount': 25836, 'total_yearly_units': 10020, 'customer_name': 'MUHAMMAD ARIF', 'issue_date': '2025-02-14', 'due_date': '2025-02-23'}
INFO 2025-02-27 01:13:21,019 quote_views 1992 1476 Request content type: application/json
INFO 2025-02-27 01:13:21,019 quote_views 1992 1476 Field units_consumed: value=388, type=<class 'int'>
INFO 2025-02-27 01:13:21,019 quote_views 1992 1476 Field amount: value=25836, type=<class 'int'>
INFO 2025-02-27 01:13:21,019 quote_views 1992 1476 Field total_yearly_units: value=10020, type=<class 'int'>
INFO 2025-02-27 01:13:21,019 quote_views 1992 1476 Converted values - units: 388.0, amount: 25836.0, yearly: 10020.0
INFO 2025-02-27 01:13:21,019 quote_views 1992 1476 Passing to quote service:
INFO 2025-02-27 01:13:21,019 quote_service 1992 1476 === Starting Quote Generation ===
INFO 2025-02-27 01:13:21,019 quote_service 1992 1476 Received bill data: {'reference_number': '04151722337322', 'units_consumed': 388, 'amount': 25836, 'total_yearly_units': 10020, 'customer_name': 'MUHAMMAD ARIF', 'issue_date': '2025-02-14', 'due_date': '2025-02-23'}
INFO 2025-02-27 01:13:21,019 quote_service 1992 1476 Sanitized data: {'reference_number': '04151722337322', 'units_consumed': 388.0, 'amount': 25836.0, 'total_yearly_units': 10020.0, 'customer_name': 'MUHAMMAD ARIF', 'customer_address': '', 'issue_date': '2025-02-14', 'due_date': '2025-02-23'}
INFO 2025-02-27 01:13:21,019 quote_service 1992 1476 Calculated system size: 13kW
INFO 2025-02-27 01:13:21,023 quote_service 1992 1476 Components selected - Panel: Canada Solar, Count: 23, Inverter: MaxPower
INFO 2025-02-27 01:13:21,023 quote_service 1992 1476 Calculating costs for 13kW system with 23 panels
INFO 2025-02-27 01:13:21,023 inventory_service 1992 1476 Fetching bracket costs for system size: 13kW
INFO 2025-02-27 01:13:21,024 inventory_service 1992 1476 Retrieved costs: {'dc_cable': 15000.0, 'ac_cable': 10000.0, 'accessories': 20000.0}
INFO 2025-02-27 01:13:21,024 quote_service 1992 1476 Retrieved bracket costs: {'dc_cable': 15000.0, 'ac_cable': 10000.0, 'accessories': 20000.0}
INFO 2025-02-27 01:13:21,025 quote_service 1992 1476 Final calculated costs: {'net_metering': 250000.0, 'installation': 105300.0, 'frame': 70200.0, 'labor': 104.0, 'dc_cable': 15000.0, 'ac_cable': 10000.0, 'accessories': 20000.0, 'transport': 200.0, 'margin': 0, 'vat': 0}
INFO 2025-02-27 01:13:21,025 quote_service 1992 1476 Calculated costs: {'net_metering': 250000.0, 'installation': 105300.0, 'frame': 70200.0, 'labor': 104.0, 'dc_cable': 15000.0, 'ac_cable': 10000.0, 'accessories': 20000.0, 'transport': 200.0, 'margin': 0, 'vat': 0}
ERROR 2025-02-27 01:13:21,025 quote_service 1992 1476 Unexpected error in quote generation
Traceback (most recent call last):
  File "D:\Projects\Solar_Sizing_Bill_Calculator_With_AI_Backend\solar\services\quote_service.py", line 115, in generate_quote
    'price': float(panel.price) * panels_needed * panel.power
             ~~~~~~~~~~~~~~~~~~~~~~~~~~~~~~~~~~~^~~~~~~~~~~~~
TypeError: unsupported operand type(s) for *: 'float' and 'decimal.Decimal'
ERROR 2025-02-27 01:13:21,026 quote_views 1992 1476 Error in quote generation
Traceback (most recent call last):
  File "D:\Projects\Solar_Sizing_Bill_Calculator_With_AI_Backend\solar\services\quote_service.py", line 115, in generate_quote
    'price': float(panel.price) * panels_needed * panel.power
             ~~~~~~~~~~~~~~~~~~~~~~~~~~~~~~~~~~~^~~~~~~~~~~~~
TypeError: unsupported operand type(s) for *: 'float' and 'decimal.Decimal'

During handling of the above exception, another exception occurred:

Traceback (most recent call last):
  File "D:\Projects\Solar_Sizing_Bill_Calculator_With_AI_Backend\solar\views\quote_views.py", line 46, in post
    quote_data = QuoteService.generate_quote(request.data)
  File "D:\Projects\Solar_Sizing_Bill_Calculator_With_AI_Backend\solar\services\quote_service.py", line 156, in generate_quote
    raise AppError(
    ...<3 lines>...
    )
solar.middleware.error_handler.AppError: Failed to generate quote
INFO 2025-02-27 01:14:18,633 quote_views 22052 13096 Raw quote generation request data: {'reference_number': '04151722337322', 'units_consumed': 388, 'amount': 25836, 'total_yearly_units': 10020, 'customer_name': 'MUHAMMAD ARIF', 'issue_date': '2025-02-14', 'due_date': '2025-02-23'}
INFO 2025-02-27 01:14:18,633 quote_views 22052 13096 Request content type: application/json
INFO 2025-02-27 01:14:18,633 quote_views 22052 13096 Field units_consumed: value=388, type=<class 'int'>
INFO 2025-02-27 01:14:18,633 quote_views 22052 13096 Field amount: value=25836, type=<class 'int'>
INFO 2025-02-27 01:14:18,633 quote_views 22052 13096 Field total_yearly_units: value=10020, type=<class 'int'>
INFO 2025-02-27 01:14:18,633 quote_views 22052 13096 Converted values - units: 388.0, amount: 25836.0, yearly: 10020.0
INFO 2025-02-27 01:14:18,633 quote_views 22052 13096 Passing to quote service:
INFO 2025-02-27 01:14:18,634 quote_service 22052 13096 === Starting Quote Generation ===
INFO 2025-02-27 01:14:18,634 quote_service 22052 13096 Received bill data: {'reference_number': '04151722337322', 'units_consumed': 388, 'amount': 25836, 'total_yearly_units': 10020, 'customer_name': 'MUHAMMAD ARIF', 'issue_date': '2025-02-14', 'due_date': '2025-02-23'}
INFO 2025-02-27 01:14:18,634 quote_service 22052 13096 Sanitized data: {'reference_number': '04151722337322', 'units_consumed': 388.0, 'amount': 25836.0, 'total_yearly_units': 10020.0, 'customer_name': 'MUHAMMAD ARIF', 'issue_date': '2025-02-14', 'due_date': '2025-02-23'}
INFO 2025-02-27 01:14:18,634 quote_service 22052 13096 Calculated system size: 13kW
INFO 2025-02-27 01:14:18,637 quote_service 22052 13096 Components selected - Panel: Canada Solar, Count: 23, Inverter: MaxPower
INFO 2025-02-27 01:14:18,638 quote_service 22052 13096 Calculating costs for 13kW system with 23 panels
INFO 2025-02-27 01:14:18,638 inventory_service 22052 13096 Fetching bracket costs for system size: 13kW
INFO 2025-02-27 01:14:18,639 inventory_service 22052 13096 Retrieved costs: {'dc_cable': 15000.0, 'ac_cable': 10000.0, 'accessories': 20000.0}
INFO 2025-02-27 01:14:18,639 quote_service 22052 13096 Retrieved bracket costs: {'dc_cable': 15000.0, 'ac_cable': 10000.0, 'accessories': 20000.0}
INFO 2025-02-27 01:14:18,639 quote_service 22052 13096 Final calculated costs: {'net_metering': 250000.0, 'installation': 105300.0, 'frame': 70200.0, 'labor': 104.0, 'dc_cable': 15000.0, 'ac_cable': 10000.0, 'accessories': 20000.0, 'transport': 200.0, 'margin': 0, 'vat': 0}
INFO 2025-02-27 01:14:18,639 quote_service 22052 13096 Calculated costs: {'net_metering': 250000.0, 'installation': 105300.0, 'frame': 70200.0, 'labor': 104.0, 'dc_cable': 15000.0, 'ac_cable': 10000.0, 'accessories': 20000.0, 'transport': 200.0, 'margin': 0, 'vat': 0}
ERROR 2025-02-27 01:14:18,640 quote_service 22052 13096 Missing required field: 'customer_address'
ERROR 2025-02-27 01:14:18,640 quote_views 22052 13096 Error in quote generation
Traceback (most recent call last):
  File "D:\Projects\Solar_Sizing_Bill_Calculator_With_AI_Backend\solar\services\quote_service.py", line 124, in generate_quote
    'customer_address': sanitized_data['customer_address'],
                        ~~~~~~~~~~~~~~^^^^^^^^^^^^^^^^^^^^
KeyError: 'customer_address'

During handling of the above exception, another exception occurred:

Traceback (most recent call last):
  File "D:\Projects\Solar_Sizing_Bill_Calculator_With_AI_Backend\solar\views\quote_views.py", line 46, in post
    quote_data = QuoteService.generate_quote(request.data)
  File "D:\Projects\Solar_Sizing_Bill_Calculator_With_AI_Backend\solar\services\quote_service.py", line 143, in generate_quote
    raise AppError(
    ...<2 lines>...
    )
solar.middleware.error_handler.AppError: Missing required field: 'customer_address'
INFO 2025-02-27 01:14:51,933 quote_views 25448 25404 Raw quote generation request data: {'reference_number': '04151722337322', 'units_consumed': 388, 'amount': 25836, 'total_yearly_units': 10020, 'customer_name': 'MUHAMMAD ARIF', 'issue_date': '2025-02-14', 'due_date': '2025-02-23'}
INFO 2025-02-27 01:14:51,933 quote_views 25448 25404 Request content type: application/json
INFO 2025-02-27 01:14:51,933 quote_views 25448 25404 Field units_consumed: value=388, type=<class 'int'>
INFO 2025-02-27 01:14:51,933 quote_views 25448 25404 Field amount: value=25836, type=<class 'int'>
INFO 2025-02-27 01:14:51,934 quote_views 25448 25404 Field total_yearly_units: value=10020, type=<class 'int'>
INFO 2025-02-27 01:14:51,934 quote_views 25448 25404 Converted values - units: 388.0, amount: 25836.0, yearly: 10020.0
INFO 2025-02-27 01:14:51,934 quote_views 25448 25404 Passing to quote service:
INFO 2025-02-27 01:14:51,934 quote_service 25448 25404 === Starting Quote Generation ===
INFO 2025-02-27 01:14:51,934 quote_service 25448 25404 Received bill data: {'reference_number': '04151722337322', 'units_consumed': 388, 'amount': 25836, 'total_yearly_units': 10020, 'customer_name': 'MUHAMMAD ARIF', 'issue_date': '2025-02-14', 'due_date': '2025-02-23'}
INFO 2025-02-27 01:14:51,934 quote_service 25448 25404 Sanitized data: {'reference_number': '04151722337322', 'units_consumed': 388.0, 'amount': 25836.0, 'total_yearly_units': 10020.0, 'customer_name': 'MUHAMMAD ARIF', 'issue_date': '2025-02-14', 'due_date': '2025-02-23'}
INFO 2025-02-27 01:14:51,934 quote_service 25448 25404 Calculated system size: 13kW
INFO 2025-02-27 01:14:51,937 quote_service 25448 25404 Components selected - Panel: Canada Solar, Count: 23, Inverter: MaxPower
INFO 2025-02-27 01:14:51,938 quote_service 25448 25404 Calculating costs for 13kW system with 23 panels
INFO 2025-02-27 01:14:51,938 inventory_service 25448 25404 Fetching bracket costs for system size: 13kW
INFO 2025-02-27 01:14:51,939 inventory_service 25448 25404 Retrieved costs: {'dc_cable': 15000.0, 'ac_cable': 10000.0, 'accessories': 20000.0}
INFO 2025-02-27 01:14:51,939 quote_service 25448 25404 Retrieved bracket costs: {'dc_cable': 15000.0, 'ac_cable': 10000.0, 'accessories': 20000.0}
INFO 2025-02-27 01:14:51,940 quote_service 25448 25404 Final calculated costs: {'net_metering': 250000.0, 'installation': 105300.0, 'frame': 70200.0, 'labor': 104.0, 'dc_cable': 15000.0, 'ac_cable': 10000.0, 'accessories': 20000.0, 'transport': 200.0, 'margin': 0, 'vat': 0}
INFO 2025-02-27 01:14:51,940 quote_service 25448 25404 Calculated costs: {'net_metering': 250000.0, 'installation': 105300.0, 'frame': 70200.0, 'labor': 104.0, 'dc_cable': 15000.0, 'ac_cable': 10000.0, 'accessories': 20000.0, 'transport': 200.0, 'margin': 0, 'vat': 0}
ERROR 2025-02-27 01:14:51,940 quote_service 25448 25404 Missing required field: 'customer_address'
ERROR 2025-02-27 01:14:51,940 quote_views 25448 25404 Error in quote generation
Traceback (most recent call last):
  File "D:\Projects\Solar_Sizing_Bill_Calculator_With_AI_Backend\solar\services\quote_service.py", line 124, in generate_quote
    'customer_address': sanitized_data['customer_address'],
                        ~~~~~~~~~~~~~~^^^^^^^^^^^^^^^^^^^^
KeyError: 'customer_address'

During handling of the above exception, another exception occurred:

Traceback (most recent call last):
  File "D:\Projects\Solar_Sizing_Bill_Calculator_With_AI_Backend\solar\views\quote_views.py", line 46, in post
    quote_data = QuoteService.generate_quote(request.data)
  File "D:\Projects\Solar_Sizing_Bill_Calculator_With_AI_Backend\solar\services\quote_service.py", line 143, in generate_quote
    raise AppError(
    ...<2 lines>...
    )
solar.middleware.error_handler.AppError: Missing required field: 'customer_address'
INFO 2025-02-27 01:17:48,199 quote_views 25572 25444 Raw quote generation request data: {'reference_number': '04151722337322', 'units_consumed': 388, 'amount': 25836, 'total_yearly_units': 10020, 'customer_name': 'MUHAMMAD ARIF', 'issue_date': '2025-02-14', 'due_date': '2025-02-23'}
INFO 2025-02-27 01:17:48,199 quote_views 25572 25444 Request content type: application/json
INFO 2025-02-27 01:17:48,199 quote_views 25572 25444 Field units_consumed: value=388, type=<class 'int'>
INFO 2025-02-27 01:17:48,199 quote_views 25572 25444 Field amount: value=25836, type=<class 'int'>
INFO 2025-02-27 01:17:48,199 quote_views 25572 25444 Field total_yearly_units: value=10020, type=<class 'int'>
INFO 2025-02-27 01:17:48,199 quote_views 25572 25444 Converted values - units: 388.0, amount: 25836.0, yearly: 10020.0
INFO 2025-02-27 01:17:48,199 quote_views 25572 25444 Passing to quote service:
INFO 2025-02-27 01:17:48,200 quote_service 25572 25444 === Starting Quote Generation ===
INFO 2025-02-27 01:17:48,200 quote_service 25572 25444 Received bill data: {'reference_number': '04151722337322', 'units_consumed': 388, 'amount': 25836, 'total_yearly_units': 10020, 'customer_name': 'MUHAMMAD ARIF', 'issue_date': '2025-02-14', 'due_date': '2025-02-23'}
INFO 2025-02-27 01:17:48,200 quote_service 25572 25444 Sanitized data: {'reference_number': '04151722337322', 'units_consumed': 388.0, 'amount': 25836.0, 'total_yearly_units': 10020.0, 'customer_name': 'MUHAMMAD ARIF', 'issue_date': '2025-02-14', 'due_date': '2025-02-23'}
INFO 2025-02-27 01:17:48,200 quote_service 25572 25444 Calculated system size: 13kW
INFO 2025-02-27 01:17:48,203 quote_service 25572 25444 Components selected - Panel: Canada Solar, Count: 23, Inverter: MaxPower
INFO 2025-02-27 01:17:48,203 quote_service 25572 25444 Calculating costs for 13kW system with 23 panels
INFO 2025-02-27 01:17:48,203 inventory_service 25572 25444 Fetching bracket costs for system size: 13kW
INFO 2025-02-27 01:17:48,204 inventory_service 25572 25444 Retrieved costs: {'dc_cable': 15000.0, 'ac_cable': 10000.0, 'accessories': 20000.0}
INFO 2025-02-27 01:17:48,204 quote_service 25572 25444 Retrieved bracket costs: {'dc_cable': 15000.0, 'ac_cable': 10000.0, 'accessories': 20000.0}
INFO 2025-02-27 01:17:48,204 quote_service 25572 25444 Final calculated costs: {'net_metering': 250000.0, 'installation': 105300.0, 'frame': 70200.0, 'labor': 104.0, 'dc_cable': 15000.0, 'ac_cable': 10000.0, 'accessories': 20000.0, 'margin': 0, 'vat': 0}
INFO 2025-02-27 01:17:48,204 quote_service 25572 25444 Calculated costs: {'net_metering': 250000.0, 'installation': 105300.0, 'frame': 70200.0, 'labor': 104.0, 'dc_cable': 15000.0, 'ac_cable': 10000.0, 'accessories': 20000.0, 'margin': 0, 'vat': 0}
ERROR 2025-02-27 01:17:48,204 quote_service 25572 25444 Missing required field: 'customer_address'
ERROR 2025-02-27 01:17:48,204 quote_views 25572 25444 Error in quote generation
Traceback (most recent call last):
  File "D:\Projects\Solar_Sizing_Bill_Calculator_With_AI_Backend\solar\services\quote_service.py", line 124, in generate_quote
    'customer_address': sanitized_data['customer_address'],
                        ~~~~~~~~~~~~~~^^^^^^^^^^^^^^^^^^^^
KeyError: 'customer_address'

During handling of the above exception, another exception occurred:

Traceback (most recent call last):
  File "D:\Projects\Solar_Sizing_Bill_Calculator_With_AI_Backend\solar\views\quote_views.py", line 46, in post
    quote_data = QuoteService.generate_quote(request.data)
  File "D:\Projects\Solar_Sizing_Bill_Calculator_With_AI_Backend\solar\services\quote_service.py", line 143, in generate_quote
    raise AppError(
    ...<2 lines>...
    )
solar.middleware.error_handler.AppError: Missing required field: 'customer_address'
ERROR 2025-02-27 01:20:04,467 quote_service 15832 27048 Missing required field: 'customer_address'
ERROR 2025-02-27 01:20:04,467 quote_views 15832 27048 Error in quote generation
Traceback (most recent call last):
  File "D:\Projects\Solar_Sizing_Bill_Calculator_With_AI_Backend\solar\services\quote_service.py", line 124, in generate_quote
    'customer_address': sanitized_data['customer_address'],
                        ~~~~~~~~~~~~~~^^^^^^^^^^^^^^^^^^^^
KeyError: 'customer_address'

During handling of the above exception, another exception occurred:

Traceback (most recent call last):
  File "D:\Projects\Solar_Sizing_Bill_Calculator_With_AI_Backend\solar\views\quote_views.py", line 46, in post
    quote_data = QuoteService.generate_quote(request.data)
  File "D:\Projects\Solar_Sizing_Bill_Calculator_With_AI_Backend\solar\services\quote_service.py", line 143, in generate_quote
    raise AppError(
    ...<2 lines>...
    )
solar.middleware.error_handler.AppError: Missing required field: 'customer_address'
ERROR 2025-02-27 01:20:28,038 quote_service 16900 12524 Missing required field: 'customer_address'
ERROR 2025-02-27 01:20:28,038 quote_views 16900 12524 Error in quote generation
Traceback (most recent call last):
  File "D:\Projects\Solar_Sizing_Bill_Calculator_With_AI_Backend\solar\services\quote_service.py", line 124, in generate_quote
    'customer_address': sanitized_data['customer_address'],
                        ~~~~~~~~~~~~~~^^^^^^^^^^^^^^^^^^^^
KeyError: 'customer_address'

During handling of the above exception, another exception occurred:

Traceback (most recent call last):
  File "D:\Projects\Solar_Sizing_Bill_Calculator_With_AI_Backend\solar\views\quote_views.py", line 46, in post
    quote_data = QuoteService.generate_quote(request.data)
  File "D:\Projects\Solar_Sizing_Bill_Calculator_With_AI_Backend\solar\services\quote_service.py", line 143, in generate_quote
    raise AppError(
    ...<2 lines>...
    )
solar.middleware.error_handler.AppError: Missing required field: 'customer_address'
ERROR 2025-02-27 01:20:57,384 quote_service 14880 2480 Missing required field: 'transport'
ERROR 2025-02-27 01:20:57,384 quote_views 14880 2480 Error in quote generation
Traceback (most recent call last):
  File "D:\Projects\Solar_Sizing_Bill_Calculator_With_AI_Backend\solar\services\quote_service.py", line 135, in generate_quote
    'costs': cls._format_costs_breakdown(costs)
             ~~~~~~~~~~~~~~~~~~~~~~~~~~~^^^^^^^
  File "D:\Projects\Solar_Sizing_Bill_Calculator_With_AI_Backend\solar\services\quote_service.py", line 452, in _format_costs_breakdown
    costs['transport'],
    ~~~~~^^^^^^^^^^^^^
KeyError: 'transport'

During handling of the above exception, another exception occurred:

Traceback (most recent call last):
  File "D:\Projects\Solar_Sizing_Bill_Calculator_With_AI_Backend\solar\views\quote_views.py", line 46, in post
    quote_data = QuoteService.generate_quote(request.data)
  File "D:\Projects\Solar_Sizing_Bill_Calculator_With_AI_Backend\solar\services\quote_service.py", line 143, in generate_quote
    raise AppError(
    ...<2 lines>...
    )
solar.middleware.error_handler.AppError: Missing required field: 'transport'
ERROR 2025-02-28 01:12:04,921 quote_views 22784 9976 Error in quote generation
Traceback (most recent call last):
  File "D:\Projects\Solar_Sizing_Bill_Calculator_With_AI_Backend\solar\views\quote_views.py", line 51, in post
    system_size = quote_data['data']['systemDetails']['system_size']
                  ~~~~~~~~~~~~~~~~~~~~~~~~~~~~~~~~~~~^^^^^^^^^^^^^^^
KeyError: 'system_size'
ERROR 2025-02-28 01:12:49,937 quote_views 7548 15912 Error in quote generation
Traceback (most recent call last):
  File "D:\Projects\Solar_Sizing_Bill_Calculator_With_AI_Backend\solar\views\quote_views.py", line 51, in post
    system_size = quote_data['data']['systemDetails']['system_size']
                  ~~~~~~~~~~~~~~~~~~~~~~~~~~~~~~~~~~~^^^^^^^^^^^^^^^
KeyError: 'system_size'
ERROR 2025-02-28 01:13:20,921 quote_views 12456 10100 Error in quote generation
Traceback (most recent call last):
  File "D:\Projects\Solar_Sizing_Bill_Calculator_With_AI_Backend\solar\views\quote_views.py", line 59, in post
    cabling_costs = int(quote_data['data']['costs']['details']['dc_cabling']) + int(quote_data['data']['costs']['details']['ac_cabling'])
                        ~~~~~~~~~~~~~~~~~~~~~~~~~~~~~~~~~~~~~~^^^^^^^^^^^^^^
KeyError: 'dc_cabling'
ERROR 2025-02-28 01:14:49,563 quote_views 4380 7944 Error in quote generation
Traceback (most recent call last):
  File "D:\Projects\Solar_Sizing_Bill_Calculator_With_AI_Backend\solar\views\quote_views.py", line 59, in post
    cabling_costs = int(quote_data['data']['costs']['details']['dc_cable']) + int(quote_data['data']['costs']['details']['ac_cable'])
                    ~~~^^^^^^^^^^^^^^^^^^^^^^^^^^^^^^^^^^^^^^^^^^^^^^^^^^^^
TypeError: int() argument must be a string, a bytes-like object or a real number, not 'dict'
ERROR 2025-02-28 01:16:08,572 quote_views 22012 1828 Error in quote generation
Traceback (most recent call last):
  File "D:\Projects\Solar_Sizing_Bill_Calculator_With_AI_Backend\solar\views\quote_views.py", line 61, in post
    cabling_costs = dc_cable + ac_cable
                    ~~~~~~~~~^~~~~~~~~~
TypeError: unsupported operand type(s) for +: 'dict' and 'dict'
ERROR 2025-02-28 01:18:05,997 quote_views 17568 19180 Error in quote generation
Traceback (most recent call last):
  File "D:\Projects\Solar_Sizing_Bill_Calculator_With_AI_Backend\solar\views\quote_views.py", line 59, in post
    dc_cable = quote_data['data']['costs']['details']['dc_cable']['cost']
               ~~~~~~~~~~~~~~~~~~~~~~~~~~~~~~~~~~~~~~~~~~~~~~~~~~^^^^^^^^
KeyError: 'cost'
ERROR 2025-02-28 01:19:37,599 quote_views 22144 18884 Error in quote generation
Traceback (most recent call last):
  File "D:\Projects\Solar_Sizing_Bill_Calculator_With_AI_Backend\solar\views\quote_views.py", line 66, in post
    generate_invoice(system_size, panels, panel_power, inverter_price,
    ~~~~~~~~~~~~~~~~^^^^^^^^^^^^^^^^^^^^^^^^^^^^^^^^^^^^^^^^^^^^^^^^^^
             inverter_brand, panel_price, net_metering,
             ^^^^^^^^^^^^^^^^^^^^^^^^^^^^^^^^^^^^^^^^^^
             installation_costs, cabling_costs, frame_costs,
             ^^^^^^^^^^^^^^^^^^^^^^^^^^^^^^^^^^^^^^^^^^^^^^^
             electrical_and_mechanical_costs, total_cost, customer_name, customer_address, customer_phone)
             ^^^^^^^^^^^^^^^^^^^^^^^^^^^^^^^^^^^^^^^^^^^^^^^^^^^^^^^^^^^^^^^^^^^^^^^^^^^^^^^^^^^^^^^^^^^^^
  File "D:\Projects\Solar_Sizing_Bill_Calculator_With_AI_Backend\solar\invoice_generator\invoicemaker.py", line 232, in generate_invoice
    pdf.cell(20, 20, txt=f"{int(float(structure_costs))}", border="L,R,T", ln=1, align="R", fill=True)
                                ~~~~~^^^^^^^^^^^^^^^^^
TypeError: float() argument must be a string or a real number, not 'dict'
ERROR 2025-02-28 01:20:30,856 quote_views 14276 8992 Error in quote generation
Traceback (most recent call last):
  File "D:\Projects\Solar_Sizing_Bill_Calculator_With_AI_Backend\solar\views\quote_views.py", line 67, in post
    generate_invoice(system_size, panels, panel_power, inverter_price,
    ~~~~~~~~~~~~~~~~^^^^^^^^^^^^^^^^^^^^^^^^^^^^^^^^^^^^^^^^^^^^^^^^^^
             inverter_brand, panel_price, net_metering,
             ^^^^^^^^^^^^^^^^^^^^^^^^^^^^^^^^^^^^^^^^^^
             installation_costs, cabling_costs, frame_costs,
             ^^^^^^^^^^^^^^^^^^^^^^^^^^^^^^^^^^^^^^^^^^^^^^^
             electrical_and_mechanical_costs, total_cost, customer_name, customer_address, customer_phone)
             ^^^^^^^^^^^^^^^^^^^^^^^^^^^^^^^^^^^^^^^^^^^^^^^^^^^^^^^^^^^^^^^^^^^^^^^^^^^^^^^^^^^^^^^^^^^^^
  File "D:\Projects\Solar_Sizing_Bill_Calculator_With_AI_Backend\solar\invoice_generator\invoicemaker.py", line 233, in generate_invoice
    pdf.cell(20, 20, txt=f"{int(float(structure_costs))}", border="L,R,T", ln=1, align="R", fill=True)
                                ~~~~~^^^^^^^^^^^^^^^^^
TypeError: float() argument must be a string or a real number, not 'dict'
ERROR 2025-03-23 02:21:56,263 bill_views 29628 6808 Unexpected error in bill validation
Traceback (most recent call last):
  File "C:\Users\abdul\AppData\Local\Programs\Python\Python313\Lib\site-packages\rest_framework\parsers.py", line 66, in parse
    return json.load(decoded_stream, parse_constant=parse_constant)
           ~~~~~~~~~^^^^^^^^^^^^^^^^^^^^^^^^^^^^^^^^^^^^^^^^^^^^^^^
  File "C:\Users\abdul\AppData\Local\Programs\Python\Python313\Lib\site-packages\rest_framework\utils\json.py", line 31, in load
    return json.load(*args, **kwargs)
           ~~~~~~~~~^^^^^^^^^^^^^^^^^
  File "C:\Users\abdul\AppData\Local\Programs\Python\Python313\Lib\json\__init__.py", line 293, in load
    return loads(fp.read(),
        cls=cls, object_hook=object_hook,
        parse_float=parse_float, parse_int=parse_int,
        parse_constant=parse_constant, object_pairs_hook=object_pairs_hook, **kw)
  File "C:\Users\abdul\AppData\Local\Programs\Python\Python313\Lib\json\__init__.py", line 359, in loads
    return cls(**kw).decode(s)
           ~~~~~~~~~~~~~~~~^^^
  File "C:\Users\abdul\AppData\Local\Programs\Python\Python313\Lib\json\decoder.py", line 345, in decode
    obj, end = self.raw_decode(s, idx=_w(s, 0).end())
               ~~~~~~~~~~~~~~~^^^^^^^^^^^^^^^^^^^^^^^
  File "C:\Users\abdul\AppData\Local\Programs\Python\Python313\Lib\json\decoder.py", line 361, in raw_decode
    obj, end = self.scan_once(s, idx)
               ~~~~~~~~~~~~~~^^^^^^^^
json.decoder.JSONDecodeError: Expecting property name enclosed in double quotes: line 2 column 3 (char 4)

During handling of the above exception, another exception occurred:

Traceback (most recent call last):
  File "D:\Projects\Solar_Sizing_Bill_Calculator_With_AI_Backend\solar\views\bill_views.py", line 16, in post
    reference_number = request.data.get('reference_number')
                       ^^^^^^^^^^^^
  File "C:\Users\abdul\AppData\Local\Programs\Python\Python313\Lib\site-packages\rest_framework\request.py", line 220, in data
    self._load_data_and_files()
    ~~~~~~~~~~~~~~~~~~~~~~~~~^^
  File "C:\Users\abdul\AppData\Local\Programs\Python\Python313\Lib\site-packages\rest_framework\request.py", line 283, in _load_data_and_files
    self._data, self._files = self._parse()
                              ~~~~~~~~~~~^^
  File "C:\Users\abdul\AppData\Local\Programs\Python\Python313\Lib\site-packages\rest_framework\request.py", line 358, in _parse
    parsed = parser.parse(stream, media_type, self.parser_context)
  File "C:\Users\abdul\AppData\Local\Programs\Python\Python313\Lib\site-packages\rest_framework\parsers.py", line 68, in parse
    raise ParseError('JSON parse error - %s' % str(exc))
rest_framework.exceptions.ParseError: JSON parse error - Expecting property name enclosed in double quotes: line 2 column 3 (char 4)
ERROR 2025-03-23 02:25:26,548 bill_views 17352 16768 Unexpected error in bill validation
Traceback (most recent call last):
  File "C:\Users\abdul\AppData\Local\Programs\Python\Python313\Lib\site-packages\rest_framework\parsers.py", line 66, in parse
    return json.load(decoded_stream, parse_constant=parse_constant)
           ~~~~~~~~~^^^^^^^^^^^^^^^^^^^^^^^^^^^^^^^^^^^^^^^^^^^^^^^
  File "C:\Users\abdul\AppData\Local\Programs\Python\Python313\Lib\site-packages\rest_framework\utils\json.py", line 31, in load
    return json.load(*args, **kwargs)
           ~~~~~~~~~^^^^^^^^^^^^^^^^^
  File "C:\Users\abdul\AppData\Local\Programs\Python\Python313\Lib\json\__init__.py", line 293, in load
    return loads(fp.read(),
        cls=cls, object_hook=object_hook,
        parse_float=parse_float, parse_int=parse_int,
        parse_constant=parse_constant, object_pairs_hook=object_pairs_hook, **kw)
  File "C:\Users\abdul\AppData\Local\Programs\Python\Python313\Lib\json\__init__.py", line 359, in loads
    return cls(**kw).decode(s)
           ~~~~~~~~~~~~~~~~^^^
  File "C:\Users\abdul\AppData\Local\Programs\Python\Python313\Lib\json\decoder.py", line 345, in decode
    obj, end = self.raw_decode(s, idx=_w(s, 0).end())
               ~~~~~~~~~~~~~~~^^^^^^^^^^^^^^^^^^^^^^^
  File "C:\Users\abdul\AppData\Local\Programs\Python\Python313\Lib\json\decoder.py", line 361, in raw_decode
    obj, end = self.scan_once(s, idx)
               ~~~~~~~~~~~~~~^^^^^^^^
json.decoder.JSONDecodeError: Expecting property name enclosed in double quotes: line 2 column 3 (char 4)

During handling of the above exception, another exception occurred:

Traceback (most recent call last):
  File "D:\Projects\Solar_Sizing_Bill_Calculator_With_AI_Backend\solar\views\bill_views.py", line 16, in post
    reference_number = request.data.get('reference_number')
                       ^^^^^^^^^^^^
  File "C:\Users\abdul\AppData\Local\Programs\Python\Python313\Lib\site-packages\rest_framework\request.py", line 220, in data
    self._load_data_and_files()
    ~~~~~~~~~~~~~~~~~~~~~~~~~^^
  File "C:\Users\abdul\AppData\Local\Programs\Python\Python313\Lib\site-packages\rest_framework\request.py", line 283, in _load_data_and_files
    self._data, self._files = self._parse()
                              ~~~~~~~~~~~^^
  File "C:\Users\abdul\AppData\Local\Programs\Python\Python313\Lib\site-packages\rest_framework\request.py", line 358, in _parse
    parsed = parser.parse(stream, media_type, self.parser_context)
  File "C:\Users\abdul\AppData\Local\Programs\Python\Python313\Lib\site-packages\rest_framework\parsers.py", line 68, in parse
    raise ParseError('JSON parse error - %s' % str(exc))
rest_framework.exceptions.ParseError: JSON parse error - Expecting property name enclosed in double quotes: line 2 column 3 (char 4)
ERROR 2025-03-23 02:25:58,412 bill_views 8412 2884 Unexpected error in bill validation
Traceback (most recent call last):
  File "C:\Users\abdul\AppData\Local\Programs\Python\Python313\Lib\site-packages\rest_framework\parsers.py", line 66, in parse
    return json.load(decoded_stream, parse_constant=parse_constant)
           ~~~~~~~~~^^^^^^^^^^^^^^^^^^^^^^^^^^^^^^^^^^^^^^^^^^^^^^^
  File "C:\Users\abdul\AppData\Local\Programs\Python\Python313\Lib\site-packages\rest_framework\utils\json.py", line 31, in load
    return json.load(*args, **kwargs)
           ~~~~~~~~~^^^^^^^^^^^^^^^^^
  File "C:\Users\abdul\AppData\Local\Programs\Python\Python313\Lib\json\__init__.py", line 293, in load
    return loads(fp.read(),
        cls=cls, object_hook=object_hook,
        parse_float=parse_float, parse_int=parse_int,
        parse_constant=parse_constant, object_pairs_hook=object_pairs_hook, **kw)
  File "C:\Users\abdul\AppData\Local\Programs\Python\Python313\Lib\json\__init__.py", line 359, in loads
    return cls(**kw).decode(s)
           ~~~~~~~~~~~~~~~~^^^
  File "C:\Users\abdul\AppData\Local\Programs\Python\Python313\Lib\json\decoder.py", line 345, in decode
    obj, end = self.raw_decode(s, idx=_w(s, 0).end())
               ~~~~~~~~~~~~~~~^^^^^^^^^^^^^^^^^^^^^^^
  File "C:\Users\abdul\AppData\Local\Programs\Python\Python313\Lib\json\decoder.py", line 361, in raw_decode
    obj, end = self.scan_once(s, idx)
               ~~~~~~~~~~~~~~^^^^^^^^
json.decoder.JSONDecodeError: Expecting property name enclosed in double quotes: line 2 column 3 (char 4)

During handling of the above exception, another exception occurred:

Traceback (most recent call last):
  File "D:\Projects\Solar_Sizing_Bill_Calculator_With_AI_Backend\solar\views\bill_views.py", line 16, in post
    reference_number = request.data.get('reference_number')
                       ^^^^^^^^^^^^
  File "C:\Users\abdul\AppData\Local\Programs\Python\Python313\Lib\site-packages\rest_framework\request.py", line 220, in data
    self._load_data_and_files()
    ~~~~~~~~~~~~~~~~~~~~~~~~~^^
  File "C:\Users\abdul\AppData\Local\Programs\Python\Python313\Lib\site-packages\rest_framework\request.py", line 283, in _load_data_and_files
    self._data, self._files = self._parse()
                              ~~~~~~~~~~~^^
  File "C:\Users\abdul\AppData\Local\Programs\Python\Python313\Lib\site-packages\rest_framework\request.py", line 358, in _parse
    parsed = parser.parse(stream, media_type, self.parser_context)
  File "C:\Users\abdul\AppData\Local\Programs\Python\Python313\Lib\site-packages\rest_framework\parsers.py", line 68, in parse
    raise ParseError('JSON parse error - %s' % str(exc))
rest_framework.exceptions.ParseError: JSON parse error - Expecting property name enclosed in double quotes: line 2 column 3 (char 4)
ERROR 2025-03-23 02:26:57,757 bill_views 13656 27040 Unexpected error in bill validation
Traceback (most recent call last):
  File "C:\Users\abdul\AppData\Local\Programs\Python\Python313\Lib\site-packages\rest_framework\parsers.py", line 66, in parse
    return json.load(decoded_stream, parse_constant=parse_constant)
           ~~~~~~~~~^^^^^^^^^^^^^^^^^^^^^^^^^^^^^^^^^^^^^^^^^^^^^^^
  File "C:\Users\abdul\AppData\Local\Programs\Python\Python313\Lib\site-packages\rest_framework\utils\json.py", line 31, in load
    return json.load(*args, **kwargs)
           ~~~~~~~~~^^^^^^^^^^^^^^^^^
  File "C:\Users\abdul\AppData\Local\Programs\Python\Python313\Lib\json\__init__.py", line 293, in load
    return loads(fp.read(),
        cls=cls, object_hook=object_hook,
        parse_float=parse_float, parse_int=parse_int,
        parse_constant=parse_constant, object_pairs_hook=object_pairs_hook, **kw)
  File "C:\Users\abdul\AppData\Local\Programs\Python\Python313\Lib\json\__init__.py", line 359, in loads
    return cls(**kw).decode(s)
           ~~~~~~~~~~~~~~~~^^^
  File "C:\Users\abdul\AppData\Local\Programs\Python\Python313\Lib\json\decoder.py", line 345, in decode
    obj, end = self.raw_decode(s, idx=_w(s, 0).end())
               ~~~~~~~~~~~~~~~^^^^^^^^^^^^^^^^^^^^^^^
  File "C:\Users\abdul\AppData\Local\Programs\Python\Python313\Lib\json\decoder.py", line 361, in raw_decode
    obj, end = self.scan_once(s, idx)
               ~~~~~~~~~~~~~~^^^^^^^^
json.decoder.JSONDecodeError: Expecting property name enclosed in double quotes: line 2 column 3 (char 4)

During handling of the above exception, another exception occurred:

Traceback (most recent call last):
  File "D:\Projects\Solar_Sizing_Bill_Calculator_With_AI_Backend\solar\views\bill_views.py", line 16, in post
    reference_number = request.data.get('reference_number')
                       ^^^^^^^^^^^^
  File "C:\Users\abdul\AppData\Local\Programs\Python\Python313\Lib\site-packages\rest_framework\request.py", line 220, in data
    self._load_data_and_files()
    ~~~~~~~~~~~~~~~~~~~~~~~~~^^
  File "C:\Users\abdul\AppData\Local\Programs\Python\Python313\Lib\site-packages\rest_framework\request.py", line 283, in _load_data_and_files
    self._data, self._files = self._parse()
                              ~~~~~~~~~~~^^
  File "C:\Users\abdul\AppData\Local\Programs\Python\Python313\Lib\site-packages\rest_framework\request.py", line 358, in _parse
    parsed = parser.parse(stream, media_type, self.parser_context)
  File "C:\Users\abdul\AppData\Local\Programs\Python\Python313\Lib\site-packages\rest_framework\parsers.py", line 68, in parse
    raise ParseError('JSON parse error - %s' % str(exc))
rest_framework.exceptions.ParseError: JSON parse error - Expecting property name enclosed in double quotes: line 2 column 3 (char 4)
ERROR 2025-03-23 02:27:36,094 bill_views 15388 24896 Unexpected error in bill validation
Traceback (most recent call last):
  File "C:\Users\abdul\AppData\Local\Programs\Python\Python313\Lib\site-packages\rest_framework\parsers.py", line 66, in parse
    return json.load(decoded_stream, parse_constant=parse_constant)
           ~~~~~~~~~^^^^^^^^^^^^^^^^^^^^^^^^^^^^^^^^^^^^^^^^^^^^^^^
  File "C:\Users\abdul\AppData\Local\Programs\Python\Python313\Lib\site-packages\rest_framework\utils\json.py", line 31, in load
    return json.load(*args, **kwargs)
           ~~~~~~~~~^^^^^^^^^^^^^^^^^
  File "C:\Users\abdul\AppData\Local\Programs\Python\Python313\Lib\json\__init__.py", line 293, in load
    return loads(fp.read(),
        cls=cls, object_hook=object_hook,
        parse_float=parse_float, parse_int=parse_int,
        parse_constant=parse_constant, object_pairs_hook=object_pairs_hook, **kw)
  File "C:\Users\abdul\AppData\Local\Programs\Python\Python313\Lib\json\__init__.py", line 359, in loads
    return cls(**kw).decode(s)
           ~~~~~~~~~~~~~~~~^^^
  File "C:\Users\abdul\AppData\Local\Programs\Python\Python313\Lib\json\decoder.py", line 345, in decode
    obj, end = self.raw_decode(s, idx=_w(s, 0).end())
               ~~~~~~~~~~~~~~~^^^^^^^^^^^^^^^^^^^^^^^
  File "C:\Users\abdul\AppData\Local\Programs\Python\Python313\Lib\json\decoder.py", line 361, in raw_decode
    obj, end = self.scan_once(s, idx)
               ~~~~~~~~~~~~~~^^^^^^^^
json.decoder.JSONDecodeError: Expecting property name enclosed in double quotes: line 2 column 3 (char 4)

During handling of the above exception, another exception occurred:

Traceback (most recent call last):
  File "D:\Projects\Solar_Sizing_Bill_Calculator_With_AI_Backend\solar\views\bill_views.py", line 16, in post
    reference_number = request.data.get('reference_number')
                       ^^^^^^^^^^^^
  File "C:\Users\abdul\AppData\Local\Programs\Python\Python313\Lib\site-packages\rest_framework\request.py", line 220, in data
    self._load_data_and_files()
    ~~~~~~~~~~~~~~~~~~~~~~~~~^^
  File "C:\Users\abdul\AppData\Local\Programs\Python\Python313\Lib\site-packages\rest_framework\request.py", line 283, in _load_data_and_files
    self._data, self._files = self._parse()
                              ~~~~~~~~~~~^^
  File "C:\Users\abdul\AppData\Local\Programs\Python\Python313\Lib\site-packages\rest_framework\request.py", line 358, in _parse
    parsed = parser.parse(stream, media_type, self.parser_context)
  File "C:\Users\abdul\AppData\Local\Programs\Python\Python313\Lib\site-packages\rest_framework\parsers.py", line 68, in parse
    raise ParseError('JSON parse error - %s' % str(exc))
rest_framework.exceptions.ParseError: JSON parse error - Expecting property name enclosed in double quotes: line 2 column 3 (char 4)
ERROR 2025-03-23 02:30:10,165 bill_views 2028 23656 Unexpected error in bill validation
Traceback (most recent call last):
  File "C:\Users\abdul\AppData\Local\Programs\Python\Python313\Lib\site-packages\rest_framework\parsers.py", line 66, in parse
    return json.load(decoded_stream, parse_constant=parse_constant)
           ~~~~~~~~~^^^^^^^^^^^^^^^^^^^^^^^^^^^^^^^^^^^^^^^^^^^^^^^
  File "C:\Users\abdul\AppData\Local\Programs\Python\Python313\Lib\site-packages\rest_framework\utils\json.py", line 31, in load
    return json.load(*args, **kwargs)
           ~~~~~~~~~^^^^^^^^^^^^^^^^^
  File "C:\Users\abdul\AppData\Local\Programs\Python\Python313\Lib\json\__init__.py", line 293, in load
    return loads(fp.read(),
        cls=cls, object_hook=object_hook,
        parse_float=parse_float, parse_int=parse_int,
        parse_constant=parse_constant, object_pairs_hook=object_pairs_hook, **kw)
  File "C:\Users\abdul\AppData\Local\Programs\Python\Python313\Lib\json\__init__.py", line 359, in loads
    return cls(**kw).decode(s)
           ~~~~~~~~~~~~~~~~^^^
  File "C:\Users\abdul\AppData\Local\Programs\Python\Python313\Lib\json\decoder.py", line 345, in decode
    obj, end = self.raw_decode(s, idx=_w(s, 0).end())
               ~~~~~~~~~~~~~~~^^^^^^^^^^^^^^^^^^^^^^^
  File "C:\Users\abdul\AppData\Local\Programs\Python\Python313\Lib\json\decoder.py", line 361, in raw_decode
    obj, end = self.scan_once(s, idx)
               ~~~~~~~~~~~~~~^^^^^^^^
json.decoder.JSONDecodeError: Expecting property name enclosed in double quotes: line 2 column 3 (char 4)

During handling of the above exception, another exception occurred:

Traceback (most recent call last):
  File "D:\Projects\Solar_Sizing_Bill_Calculator_With_AI_Backend\solar\views\bill_views.py", line 16, in post
    reference_number = request.data.get('reference_number')
                       ^^^^^^^^^^^^
  File "C:\Users\abdul\AppData\Local\Programs\Python\Python313\Lib\site-packages\rest_framework\request.py", line 220, in data
    self._load_data_and_files()
    ~~~~~~~~~~~~~~~~~~~~~~~~~^^
  File "C:\Users\abdul\AppData\Local\Programs\Python\Python313\Lib\site-packages\rest_framework\request.py", line 283, in _load_data_and_files
    self._data, self._files = self._parse()
                              ~~~~~~~~~~~^^
  File "C:\Users\abdul\AppData\Local\Programs\Python\Python313\Lib\site-packages\rest_framework\request.py", line 358, in _parse
    parsed = parser.parse(stream, media_type, self.parser_context)
  File "C:\Users\abdul\AppData\Local\Programs\Python\Python313\Lib\site-packages\rest_framework\parsers.py", line 68, in parse
    raise ParseError('JSON parse error - %s' % str(exc))
rest_framework.exceptions.ParseError: JSON parse error - Expecting property name enclosed in double quotes: line 2 column 3 (char 4)
ERROR 2025-03-23 02:30:43,225 bill_views 4636 23932 Unexpected error in bill validation
Traceback (most recent call last):
  File "C:\Users\abdul\AppData\Local\Programs\Python\Python313\Lib\site-packages\rest_framework\parsers.py", line 66, in parse
    return json.load(decoded_stream, parse_constant=parse_constant)
           ~~~~~~~~~^^^^^^^^^^^^^^^^^^^^^^^^^^^^^^^^^^^^^^^^^^^^^^^
  File "C:\Users\abdul\AppData\Local\Programs\Python\Python313\Lib\site-packages\rest_framework\utils\json.py", line 31, in load
    return json.load(*args, **kwargs)
           ~~~~~~~~~^^^^^^^^^^^^^^^^^
  File "C:\Users\abdul\AppData\Local\Programs\Python\Python313\Lib\json\__init__.py", line 293, in load
    return loads(fp.read(),
        cls=cls, object_hook=object_hook,
        parse_float=parse_float, parse_int=parse_int,
        parse_constant=parse_constant, object_pairs_hook=object_pairs_hook, **kw)
  File "C:\Users\abdul\AppData\Local\Programs\Python\Python313\Lib\json\__init__.py", line 359, in loads
    return cls(**kw).decode(s)
           ~~~~~~~~~~~~~~~~^^^
  File "C:\Users\abdul\AppData\Local\Programs\Python\Python313\Lib\json\decoder.py", line 345, in decode
    obj, end = self.raw_decode(s, idx=_w(s, 0).end())
               ~~~~~~~~~~~~~~~^^^^^^^^^^^^^^^^^^^^^^^
  File "C:\Users\abdul\AppData\Local\Programs\Python\Python313\Lib\json\decoder.py", line 361, in raw_decode
    obj, end = self.scan_once(s, idx)
               ~~~~~~~~~~~~~~^^^^^^^^
json.decoder.JSONDecodeError: Expecting property name enclosed in double quotes: line 2 column 3 (char 4)

During handling of the above exception, another exception occurred:

Traceback (most recent call last):
  File "D:\Projects\Solar_Sizing_Bill_Calculator_With_AI_Backend\solar\views\bill_views.py", line 16, in post
    reference_number = request.data.get('reference_number')
                       ^^^^^^^^^^^^
  File "C:\Users\abdul\AppData\Local\Programs\Python\Python313\Lib\site-packages\rest_framework\request.py", line 220, in data
    self._load_data_and_files()
    ~~~~~~~~~~~~~~~~~~~~~~~~~^^
  File "C:\Users\abdul\AppData\Local\Programs\Python\Python313\Lib\site-packages\rest_framework\request.py", line 283, in _load_data_and_files
    self._data, self._files = self._parse()
                              ~~~~~~~~~~~^^
  File "C:\Users\abdul\AppData\Local\Programs\Python\Python313\Lib\site-packages\rest_framework\request.py", line 358, in _parse
    parsed = parser.parse(stream, media_type, self.parser_context)
  File "C:\Users\abdul\AppData\Local\Programs\Python\Python313\Lib\site-packages\rest_framework\parsers.py", line 68, in parse
    raise ParseError('JSON parse error - %s' % str(exc))
rest_framework.exceptions.ParseError: JSON parse error - Expecting property name enclosed in double quotes: line 2 column 3 (char 4)
ERROR 2025-03-23 02:31:52,199 bill_views 13780 27820 Unexpected error in bill validation
Traceback (most recent call last):
  File "C:\Users\abdul\AppData\Local\Programs\Python\Python313\Lib\site-packages\rest_framework\parsers.py", line 66, in parse
    return json.load(decoded_stream, parse_constant=parse_constant)
           ~~~~~~~~~^^^^^^^^^^^^^^^^^^^^^^^^^^^^^^^^^^^^^^^^^^^^^^^
  File "C:\Users\abdul\AppData\Local\Programs\Python\Python313\Lib\site-packages\rest_framework\utils\json.py", line 31, in load
    return json.load(*args, **kwargs)
           ~~~~~~~~~^^^^^^^^^^^^^^^^^
  File "C:\Users\abdul\AppData\Local\Programs\Python\Python313\Lib\json\__init__.py", line 293, in load
    return loads(fp.read(),
        cls=cls, object_hook=object_hook,
        parse_float=parse_float, parse_int=parse_int,
        parse_constant=parse_constant, object_pairs_hook=object_pairs_hook, **kw)
  File "C:\Users\abdul\AppData\Local\Programs\Python\Python313\Lib\json\__init__.py", line 359, in loads
    return cls(**kw).decode(s)
           ~~~~~~~~~~~~~~~~^^^
  File "C:\Users\abdul\AppData\Local\Programs\Python\Python313\Lib\json\decoder.py", line 345, in decode
    obj, end = self.raw_decode(s, idx=_w(s, 0).end())
               ~~~~~~~~~~~~~~~^^^^^^^^^^^^^^^^^^^^^^^
  File "C:\Users\abdul\AppData\Local\Programs\Python\Python313\Lib\json\decoder.py", line 361, in raw_decode
    obj, end = self.scan_once(s, idx)
               ~~~~~~~~~~~~~~^^^^^^^^
json.decoder.JSONDecodeError: Expecting property name enclosed in double quotes: line 2 column 3 (char 4)

During handling of the above exception, another exception occurred:

Traceback (most recent call last):
  File "D:\Projects\Solar_Sizing_Bill_Calculator_With_AI_Backend\solar\views\bill_views.py", line 17, in post
    reference_number = request.data.get('reference_number')
                       ^^^^^^^^^^^^
  File "C:\Users\abdul\AppData\Local\Programs\Python\Python313\Lib\site-packages\rest_framework\request.py", line 220, in data
    self._load_data_and_files()
    ~~~~~~~~~~~~~~~~~~~~~~~~~^^
  File "C:\Users\abdul\AppData\Local\Programs\Python\Python313\Lib\site-packages\rest_framework\request.py", line 283, in _load_data_and_files
    self._data, self._files = self._parse()
                              ~~~~~~~~~~~^^
  File "C:\Users\abdul\AppData\Local\Programs\Python\Python313\Lib\site-packages\rest_framework\request.py", line 358, in _parse
    parsed = parser.parse(stream, media_type, self.parser_context)
  File "C:\Users\abdul\AppData\Local\Programs\Python\Python313\Lib\site-packages\rest_framework\parsers.py", line 68, in parse
    raise ParseError('JSON parse error - %s' % str(exc))
rest_framework.exceptions.ParseError: JSON parse error - Expecting property name enclosed in double quotes: line 2 column 3 (char 4)
ERROR 2025-03-23 02:33:04,967 bill_views 13780 28436 Unexpected error in bill validation
Traceback (most recent call last):
  File "C:\Users\abdul\AppData\Local\Programs\Python\Python313\Lib\site-packages\rest_framework\parsers.py", line 66, in parse
    return json.load(decoded_stream, parse_constant=parse_constant)
           ~~~~~~~~~^^^^^^^^^^^^^^^^^^^^^^^^^^^^^^^^^^^^^^^^^^^^^^^
  File "C:\Users\abdul\AppData\Local\Programs\Python\Python313\Lib\site-packages\rest_framework\utils\json.py", line 31, in load
    return json.load(*args, **kwargs)
           ~~~~~~~~~^^^^^^^^^^^^^^^^^
  File "C:\Users\abdul\AppData\Local\Programs\Python\Python313\Lib\json\__init__.py", line 293, in load
    return loads(fp.read(),
        cls=cls, object_hook=object_hook,
        parse_float=parse_float, parse_int=parse_int,
        parse_constant=parse_constant, object_pairs_hook=object_pairs_hook, **kw)
  File "C:\Users\abdul\AppData\Local\Programs\Python\Python313\Lib\json\__init__.py", line 359, in loads
    return cls(**kw).decode(s)
           ~~~~~~~~~~~~~~~~^^^
  File "C:\Users\abdul\AppData\Local\Programs\Python\Python313\Lib\json\decoder.py", line 345, in decode
    obj, end = self.raw_decode(s, idx=_w(s, 0).end())
               ~~~~~~~~~~~~~~~^^^^^^^^^^^^^^^^^^^^^^^
  File "C:\Users\abdul\AppData\Local\Programs\Python\Python313\Lib\json\decoder.py", line 361, in raw_decode
    obj, end = self.scan_once(s, idx)
               ~~~~~~~~~~~~~~^^^^^^^^
json.decoder.JSONDecodeError: Expecting property name enclosed in double quotes: line 2 column 5 (char 8)

During handling of the above exception, another exception occurred:

Traceback (most recent call last):
  File "D:\Projects\Solar_Sizing_Bill_Calculator_With_AI_Backend\solar\views\bill_views.py", line 17, in post
    reference_number = request.data.get('reference_number')
                       ^^^^^^^^^^^^
  File "C:\Users\abdul\AppData\Local\Programs\Python\Python313\Lib\site-packages\rest_framework\request.py", line 220, in data
    self._load_data_and_files()
    ~~~~~~~~~~~~~~~~~~~~~~~~~^^
  File "C:\Users\abdul\AppData\Local\Programs\Python\Python313\Lib\site-packages\rest_framework\request.py", line 283, in _load_data_and_files
    self._data, self._files = self._parse()
                              ~~~~~~~~~~~^^
  File "C:\Users\abdul\AppData\Local\Programs\Python\Python313\Lib\site-packages\rest_framework\request.py", line 358, in _parse
    parsed = parser.parse(stream, media_type, self.parser_context)
  File "C:\Users\abdul\AppData\Local\Programs\Python\Python313\Lib\site-packages\rest_framework\parsers.py", line 68, in parse
    raise ParseError('JSON parse error - %s' % str(exc))
rest_framework.exceptions.ParseError: JSON parse error - Expecting property name enclosed in double quotes: line 2 column 5 (char 8)
ERROR 2025-03-23 02:33:27,794 bill_views 28096 3772 Unexpected error in bill validation
Traceback (most recent call last):
  File "C:\Users\abdul\AppData\Local\Programs\Python\Python313\Lib\site-packages\rest_framework\parsers.py", line 66, in parse
    return json.load(decoded_stream, parse_constant=parse_constant)
           ~~~~~~~~~^^^^^^^^^^^^^^^^^^^^^^^^^^^^^^^^^^^^^^^^^^^^^^^
  File "C:\Users\abdul\AppData\Local\Programs\Python\Python313\Lib\site-packages\rest_framework\utils\json.py", line 31, in load
    return json.load(*args, **kwargs)
           ~~~~~~~~~^^^^^^^^^^^^^^^^^
  File "C:\Users\abdul\AppData\Local\Programs\Python\Python313\Lib\json\__init__.py", line 293, in load
    return loads(fp.read(),
        cls=cls, object_hook=object_hook,
        parse_float=parse_float, parse_int=parse_int,
        parse_constant=parse_constant, object_pairs_hook=object_pairs_hook, **kw)
  File "C:\Users\abdul\AppData\Local\Programs\Python\Python313\Lib\json\__init__.py", line 359, in loads
    return cls(**kw).decode(s)
           ~~~~~~~~~~~~~~~~^^^
  File "C:\Users\abdul\AppData\Local\Programs\Python\Python313\Lib\json\decoder.py", line 345, in decode
    obj, end = self.raw_decode(s, idx=_w(s, 0).end())
               ~~~~~~~~~~~~~~~^^^^^^^^^^^^^^^^^^^^^^^
  File "C:\Users\abdul\AppData\Local\Programs\Python\Python313\Lib\json\decoder.py", line 361, in raw_decode
    obj, end = self.scan_once(s, idx)
               ~~~~~~~~~~~~~~^^^^^^^^
json.decoder.JSONDecodeError: Expecting property name enclosed in double quotes: line 2 column 5 (char 8)

During handling of the above exception, another exception occurred:

Traceback (most recent call last):
  File "D:\Projects\Solar_Sizing_Bill_Calculator_With_AI_Backend\solar\views\bill_views.py", line 17, in post
    print(request.data)
          ^^^^^^^^^^^^
  File "C:\Users\abdul\AppData\Local\Programs\Python\Python313\Lib\site-packages\rest_framework\request.py", line 220, in data
    self._load_data_and_files()
    ~~~~~~~~~~~~~~~~~~~~~~~~~^^
  File "C:\Users\abdul\AppData\Local\Programs\Python\Python313\Lib\site-packages\rest_framework\request.py", line 283, in _load_data_and_files
    self._data, self._files = self._parse()
                              ~~~~~~~~~~~^^
  File "C:\Users\abdul\AppData\Local\Programs\Python\Python313\Lib\site-packages\rest_framework\request.py", line 358, in _parse
    parsed = parser.parse(stream, media_type, self.parser_context)
  File "C:\Users\abdul\AppData\Local\Programs\Python\Python313\Lib\site-packages\rest_framework\parsers.py", line 68, in parse
    raise ParseError('JSON parse error - %s' % str(exc))
rest_framework.exceptions.ParseError: JSON parse error - Expecting property name enclosed in double quotes: line 2 column 5 (char 8)
